Workbook
Name DayToStart: #REF!
Name MonthToDisplay: #REF!
Name MonthToDisplayNumber: MATCH([1]!MonthToDisplay,월,0)
Name weekdays_reversed: {"일요일","토요일","금요일","목요일","수요일","화요일","월요일"}
Name 날짜눈금: 요일+주*7
Name 날짜패턴: {1,1,2,2,3,3,4,4,5,5,6,6,7}
Name ㄹ: #REF!
Name 요일: {0,1,2,3,4,5,6}
Name 요일_옵션: MATCH(DayToStart,weekdays_reversed,0)-2
Name 월: {"1월","2월","3월","4월","5월","6월","7월","8월","9월","10월","11월","12월"}
Name 이름_IP소유: [2]!테이블_IP소유[IP소유]
Name 이름_레이블정보: [2]!테이블_레이블정보[발행자 (한글)]
Name 이름_발행처구분: [2]!테이블_발행처구분[발행처 구분]
Name 이름_발행처유형명: [2]!테이블_발행처유형명[발행처 유형명]
Name 이름_부가세: [2]!테이블_부가세[부가세]
Name 이름_사업자상태: [2]!테이블_사업자상태[사업자 상태]
Name 이름_신고구분: [2]!테이블_신고구분[신고 구분]
Name 이름_신고유형: [2]!테이블_신고유형[신고 유형]
Name 이름_자사구분: [2]!테이블_자사구분[자사 구분]
Name 이름_정산구분: [2]!테이블_정산구분[정산구분]
Name 이름_정산주체: [2]!테이블_정산주체[정산 주체]
Name 이름_특별일반: [2]!테이블_특별일반[특별/일반]
Name 이름_판매상태: [2]!테이블_판매상태[판매상태]
Name 주: {0;1;2;3;4;5;6}
Name 평일: {"월요일","화요일","수요일","목요일","금요일","토요일","일요일"}
Name 후불업체: #REF!

Sheet 26.07
B2: 2026.07월 (매입) 지급 대상 유통 정산 금액 & 정산 순매출
B3: - 수성 입금 기간 : 2026.06.01~2026.06.30
I4: 합계 | J4: =SUBTOTAL(109,J6:J1048576) -> 14979646 | L4: =SUBTOTAL(109,L6:L1048576) -> 5748549 | N4: =SUBTOTAL(109,N6:N1048576) -> 446902 | O4: =SUBTOTAL(109,O6:O1048576) -> 5301647
B5: NO | C5: 항목 | D5: 판매 국가 | E5: 구분 (독/비독) | F5: 플랫폼명 | G5: 작품명 | H5: 런칭일 | I5: 서비스월 (=판매월) | J5: 총매출(A) (요약본 정산기준매출) | K5: RS율 (테라핀) | L5: 정산기준매출(B) (테라핀) | M5: RS율 (원작사) | N5: 원작료(C) (B×원작사 RS율) | O5: 정산순매출 (B－C) | P5: 비고1 | Q5: 웹소설본부 원작여부 | R5: RS 대상여부 (외주작가)
B6: 1 | C6: =VLOOKUP(G:G,list!B:D,2,FALSE) -> 외부제작 | D6: 국내 | E6: 독점 | F6: 카카오페이지_앙상블 | G6: 블러디 체어 | H6: 44629 | I6: 46143 | J6: 339575.5 | K6: 0.6 | L6: 203746 | M6: =VLOOKUP(G:G,list!B:E,4,FALSE) -> - | N6: =ROUND(IF(M6="-",0,L6*M6),0) -> 0 | O6: =L6-N6 -> 203746 | Q6: =VLOOKUP(G:G,list!B:F,5,FALSE) -> - | R6: =VLOOKUP(G:G,list!B:D,3,FALSE) -> N
B7: 2 | C7: =VLOOKUP(G:G,list!B:D,2,FALSE) -> 외부제작 | D7: 국내 | E7: 독점 | F7: 카카오페이지_앙상블 | G7: 검신 | H7: 45057 | I7: 46143 | J7: 58856 | K7: 0.6 | L7: 35315 | M7: =VLOOKUP(G:G,list!B:E,4,FALSE) -> - | N7: =ROUND(IF(M7="-",0,L7*M7),0) -> 0 | O7: =L7-N7 -> 35315 | Q7: =VLOOKUP(G:G,list!B:F,5,FALSE) -> - | R7: =VLOOKUP(G:G,list!B:D,3,FALSE) -> N
B8: 3 | C8: =VLOOKUP(G:G,list!B:D,2,FALSE) -> 외부제작 | D8: 국내 | E8: 독점 | F8: 카카오페이지_앙상블 | G8: 강호, 미치다! | H8: 45204 | I8: 46143 | J8: 292239.6 | K8: 0.6 | L8: 175345 | M8: =VLOOKUP(G:G,list!B:E,4,FALSE) -> - | N8: =ROUND(IF(M8="-",0,L8*M8),0) -> 0 | O8: =L8-N8 -> 175345 | Q8: =VLOOKUP(G:G,list!B:F,5,FALSE) -> - | R8: =VLOOKUP(G:G,list!B:D,3,FALSE) -> N
B9: 4 | C9: =VLOOKUP(G:G,list!B:D,2,FALSE) -> 원작료 | D9: 국내 | E9: 독점 | F9: 카카오페이지 | G9: 마족의 계약 | H9: 44199 | I9: 46143 | J9: 162154 | K9: 0.6 | L9: 97293 | M9: =VLOOKUP(G:G,list!B:E,4,FALSE) -> 0.1 | N9: =ROUND(IF(M9="-",0,L9*M9),0) -> 9729 | O9: =L9-N9 -> 87564 | Q9: =VLOOKUP(G:G,list!B:F,5,FALSE) -> 웹소설본부 | R9: =VLOOKUP(G:G,list!B:D,3,FALSE) -> Y
B10: 5 | C10: =VLOOKUP(G:G,list!B:D,2,FALSE) -> 원작료 | D10: 국내 | E10: 독점 | F10: 카카오페이지 | G10: 악역에게 청혼받았습니다 | H10: 44372 | I10: 46143 | J10: 114696 | K10: 0.6 | L10: 68817 | M10: =VLOOKUP(G:G,list!B:E,4,FALSE) -> 0.1 | N10: =ROUND(IF(M10="-",0,L10*M10),0) -> 6882 | O10: =L10-N10 -> 61935 | Q10: =VLOOKUP(G:G,list!B:F,5,FALSE) -> 웹소설본부 | R10: =VLOOKUP(G:G,list!B:D,3,FALSE) -> Y
B11: 6 | C11: =VLOOKUP(G:G,list!B:D,2,FALSE) -> 작가기획 | D11: 국내 | E11: 독점 | F11: 카카오페이지 | G11: 별이 빈 소원 | H11: 44608 | I11: 46143 | J11: 0 | K11: 0.6 | L11: 0 | M11: =VLOOKUP(G:G,list!B:E,4,FALSE) -> - | N11: =ROUND(IF(M11="-",0,L11*M11),0) -> 0 | O11: =L11-N11 -> 0 | P11: *매출없음 | Q11: =VLOOKUP(G:G,list!B:F,5,FALSE) -> - | R11: =VLOOKUP(G:G,list!B:D,3,FALSE) -> Y
B12: 7 | C12: =VLOOKUP(G:G,list!B:D,2,FALSE) -> 원작료 | D12: 국내 | E12: 독점 | F12: 카카오페이지 | G12: 입술 좀 빌려주세요 | H12: 44639 | I12: 46143 | J12: 101504.2 | K12: 0.6 | L12: 60903 | M12: =VLOOKUP(G:G,list!B:E,4,FALSE) -> 0.1 | N12: =ROUND(IF(M12="-",0,L12*M12),0) -> 6090 | O12: =L12-N12 -> 54813 | Q12: =VLOOKUP(G:G,list!B:F,5,FALSE) -> 웹소설본부 | R12: =VLOOKUP(G:G,list!B:D,3,FALSE) -> Y
B13: 8 | C13: =VLOOKUP(G:G,list!B:D,2,FALSE) -> 원작료 | D13: 국내 | E13: 독점 | F13: 카카오페이지 | G13: 악녀인데 남주를 주워버렸다 | H13: 44691 | I13: 46143 | J13: 39020.6 | K13: 0.6 | L13: 23413 | M13: =VLOOKUP(G:G,list!B:E,4,FALSE) -> 0.1 | N13: =ROUND(IF(M13="-",0,L13*M13),0) -> 2341 | O13: =L13-N13 -> 21072 | Q13: =VLOOKUP(G:G,list!B:F,5,FALSE) -> 웹소설본부 | R13: =VLOOKUP(G:G,list!B:D,3,FALSE) -> Y
B14: 9 | C14: =VLOOKUP(G:G,list!B:D,2,FALSE) -> 원작료 | D14: 국내 | E14: 독점 | F14: 카카오페이지 | G14: 만렙으로 사는 법 | H14: 44709 | I14: 46143 | J14: 71247 | K14: 0.6 | L14: 42748 | M14: =VLOOKUP(G:G,list!B:E,4,FALSE) -> 0.11 | N14: =ROUND(IF(M14="-",0,L14*M14),0) -> 4702 | O14: =L14-N14 -> 38046 | Q14: =VLOOKUP(G:G,list!B:F,5,FALSE) -> - | R14: =VLOOKUP(G:G,list!B:D,3,FALSE) -> N
B15: 10 | C15: =VLOOKUP(G:G,list!B:D,2,FALSE) -> 원작료 | D15: 국내 | E15: 독점 | F15: 카카오페이지 | G15: 책만 보고 탑배우! | H15: 44801 | I15: 46143 | J15: 158224 | K15: 0.6 | L15: 94934 | M15: =VLOOKUP(G:G,list!B:E,4,FALSE) -> 0.1 | N15: =ROUND(IF(M15="-",0,L15*M15),0) -> 9493 | O15: =L15-N15 -> 85441 | Q15: =VLOOKUP(G:G,list!B:F,5,FALSE) -> - | R15: =VLOOKUP(G:G,list!B:D,3,FALSE) -> Y
B16: 11 | C16: =VLOOKUP(G:G,list!B:D,2,FALSE) -> 원작료 | D16: 국내 | E16: 독점 | F16: 카카오페이지 | G16: 그 남자, 처음, 로맨틱 | H16: 44831 | I16: 46143 | J16: 34754 | K16: 0.6 | L16: 20852 | M16: =VLOOKUP(G:G,list!B:E,4,FALSE) -> 0.1 | N16: =ROUND(IF(M16="-",0,L16*M16),0) -> 2085 | O16: =L16-N16 -> 18767 | Q16: =VLOOKUP(G:G,list!B:F,5,FALSE) -> 웹소설본부 | R16: =VLOOKUP(G:G,list!B:D,3,FALSE) -> Y
B17: 12 | C17: =VLOOKUP(G:G,list!B:D,2,FALSE) -> 작가기획 | D17: 국내 | E17: 독점 | F17: 카카오페이지 | G17: 너를 만지면 | H17: 44851 | I17: 46143 | J17: 10404 | K17: 0.7 | L17: 7283 | M17: =VLOOKUP(G:G,list!B:E,4,FALSE) -> - | N17: =ROUND(IF(M17="-",0,L17*M17),0) -> 0 | O17: =L17-N17 -> 7283 | Q17: =VLOOKUP(G:G,list!B:F,5,FALSE) -> - | R17: =VLOOKUP(G:G,list!B:D,3,FALSE) -> N
B18: 13 | C18: =VLOOKUP(G:G,list!B:D,2,FALSE) -> 원작료 | D18: 국내 | E18: 독점 | F18: 카카오페이지 | G18: 악녀인데 요리를 너무 잘해 | H18: 45235 | I18: 46143 | J18: 402252.5 | K18: 0.6 | L18: 241351 | M18: =VLOOKUP(G:G,list!B:E,4,FALSE) -> 0.1 | N18: =ROUND(IF(M18="-",0,L18*M18),0) -> 24135 | O18: =L18-N18 -> 217216 | Q18: =VLOOKUP(G:G,list!B:F,5,FALSE) -> - | R18: =VLOOKUP(G:G,list!B:D,3,FALSE) -> N
B19: 14 | C19: =VLOOKUP(G:G,list!B:D,2,FALSE) -> 원작료 | D19: 국내 | E19: 독점 | F19: 카카오페이지 | G19: 검마 | H19: 45066 | I19: 46143 | J19: 63706.8 | K19: 0.7 | L19: 44594 | M19: =VLOOKUP(G:G,list!B:E,4,FALSE) -> 0.1 | N19: =ROUND(IF(M19="-",0,L19*M19),0) -> 4459 | O19: =L19-N19 -> 40135 | Q19: =VLOOKUP(G:G,list!B:F,5,FALSE) -> - | R19: =VLOOKUP(G:G,list!B:D,3,FALSE) -> Y
B20: 15 | C20: =VLOOKUP(G:G,list!B:D,2,FALSE) -> 원작료 | D20: 국내 | E20: 독점 | F20: 카카오웹툰 | G20: 마족의 계약 | H20: 44409 | I20: 46143 | J20: 23710.5 | K20: 0.6 | L20: 14226 | M20: =VLOOKUP(G:G,list!B:E,4,FALSE) -> 0.1 | N20: =ROUND(IF(M20="-",0,L20*M20),0) -> 1423 | O20: =L20-N20 -> 12803 | Q20: =VLOOKUP(G:G,list!B:F,5,FALSE) -> 웹소설본부 | R20: =VLOOKUP(G:G,list!B:D,3,FALSE) -> Y
B21: 16 | C21: =VLOOKUP(G:G,list!B:D,2,FALSE) -> 작가기획 | D21: 국내 | E21: 독점 | F21: 카카오웹툰 | G21: 너를 만지면 | H21: 44851 | I21: 46143 | J21: -10152 | K21: 0.6 | L21: -7106 | M21: =VLOOKUP(G:G,list!B:E,4,FALSE) -> - | N21: =ROUND(IF(M21="-",0,L21*M21),0) -> 0 | O21: =L21-N21 -> -7106 | Q21: =VLOOKUP(G:G,list!B:F,5,FALSE) -> - | R21: =VLOOKUP(G:G,list!B:D,3,FALSE) -> N
B22: 17 | C22: =VLOOKUP(G:G,list!B:D,2,FALSE) -> 원작료 | D22: 국내 | E22: 독점 | F22: 카카오웹툰 | G22: 입술 좀 빌려주세요 | H22: 44926 | I22: 46143 | J22: 36882.9 | K22: 0.6 | L22: 22130 | M22: =VLOOKUP(G:G,list!B:E,4,FALSE) -> 0.1 | N22: =ROUND(IF(M22="-",0,L22*M22),0) -> 2213 | O22: =L22-N22 -> 19917 | Q22: =VLOOKUP(G:G,list!B:F,5,FALSE) -> 웹소설본부 | R22: =VLOOKUP(G:G,list!B:D,3,FALSE) -> Y
B23: 18 | C23: =VLOOKUP(G:G,list!B:D,2,FALSE) -> 작가기획 | D23: 국내 | E23: 독점 | F23: 카카오웹툰 | G23: 별이 빈 소원 | H23: 44944 | I23: 46143 | J23: 0 | K23: 0.6 | L23: 0 | M23: =VLOOKUP(G:G,list!B:E,4,FALSE) -> - | N23: =ROUND(IF(M23="-",0,L23*M23),0) -> 0 | O23: =L23-N23 -> 0 | P23: *매출없음 | Q23: =VLOOKUP(G:G,list!B:F,5,FALSE) -> - | R23: =VLOOKUP(G:G,list!B:D,3,FALSE) -> Y
B24: 19 | C24: =VLOOKUP(G:G,list!B:D,2,FALSE) -> 원작료 | D24: 국내 | E24: 독점 | F24: 카카오웹툰 | G24: 책만 보고 탑배우! | H24: 44969 | I24: 46143 | J24: 64727.9 | K24: 0.6 | L24: 38837 | M24: =VLOOKUP(G:G,list!B:E,4,FALSE) -> 0.1 | N24: =ROUND(IF(M24="-",0,L24*M24),0) -> 3884 | O24: =L24-N24 -> 34953 | Q24: =VLOOKUP(G:G,list!B:F,5,FALSE) -> - | R24: =VLOOKUP(G:G,list!B:D,3,FALSE) -> Y
B25: 20 | C25: =VLOOKUP(G:G,list!B:D,2,FALSE) -> 원작료 | D25: 국내 | E25: 독점 | F25: 카카오웹툰 | G25: 그 남자, 처음, 로맨틱 | H25: 44981 | I25: 46143 | J25: 720 | K25: 0.6 | L25: 432 | M25: =VLOOKUP(G:G,list!B:E,4,FALSE) -> 0.1 | N25: =ROUND(IF(M25="-",0,L25*M25),0) -> 43 | O25: =L25-N25 -> 389 | Q25: =VLOOKUP(G:G,list!B:F,5,FALSE) -> 웹소설본부 | R25: =VLOOKUP(G:G,list!B:D,3,FALSE) -> Y
B26: 21 | C26: =VLOOKUP(G:G,list!B:D,2,FALSE) -> 원작료 | D26: 국내 | E26: 독점 | F26: 카카오웹툰 | G26: 악역에게 청혼받았습니다 | H26: 44988 | I26: 46143 | J26: 21078.7 | K26: 0.6 | L26: 12647 | M26: =VLOOKUP(G:G,list!B:E,4,FALSE) -> 0.1 | N26: =ROUND(IF(M26="-",0,L26*M26),0) -> 1265 | O26: =L26-N26 -> 11382 | Q26: =VLOOKUP(G:G,list!B:F,5,FALSE) -> 웹소설본부 | R26: =VLOOKUP(G:G,list!B:D,3,FALSE) -> Y
B27: 22 | C27: =VLOOKUP(G:G,list!B:D,2,FALSE) -> 원작료 | D27: 국내 | E27: 독점 | F27: 카카오웹툰 | G27: 악녀인데 남주를 주워버렸다 | H27: 45033 | I27: 46143 | J27: -2808 | K27: 0.6 | L27: -1685 | M27: =VLOOKUP(G:G,list!B:E,4,FALSE) -> 0.1 | N27: =ROUND(IF(M27="-",0,L27*M27),0) -> -169 | O27: =L27-N27 -> -1516 | Q27: =VLOOKUP(G:G,list!B:F,5,FALSE) -> 웹소설본부 | R27: =VLOOKUP(G:G,list!B:D,3,FALSE) -> Y
B28: 23 | C28: =VLOOKUP(G:G,list!B:D,2,FALSE) -> 외부제작 | D28: 국내 | E28: 독점 | F28: 카카오웹툰 | G28: 검신 | H28: 45057 | I28: 46143 | J28: 3448 | K28: 0.6 | L28: 2069 | M28: =VLOOKUP(G:G,list!B:E,4,FALSE) -> - | N28: =ROUND(IF(M28="-",0,L28*M28),0) -> 0 | O28: =L28-N28 -> 2069 | Q28: =VLOOKUP(G:G,list!B:F,5,FALSE) -> - | R28: =VLOOKUP(G:G,list!B:D,3,FALSE) -> N
B29: 24 | C29: =VLOOKUP(G:G,list!B:D,2,FALSE) -> 원작료 | D29: 국내 | E29: 독점 | F29: 카카오웹툰 | G29: 만렙으로 사는 법 | H29: 45057 | I29: 46143 | J29: 65356.7 | K29: 0.6 | L29: 39214 | M29: =VLOOKUP(G:G,list!B:E,4,FALSE) -> 0.11 | N29: =ROUND(IF(M29="-",0,L29*M29),0) -> 4314 | O29: =L29-N29 -> 34900 | Q29: =VLOOKUP(G:G,list!B:F,5,FALSE) -> - | R29: =VLOOKUP(G:G,list!B:D,3,FALSE) -> N
B30: 25 | C30: =VLOOKUP(G:G,list!B:D,2,FALSE) -> 외부제작 | D30: 국내 | E30: 독점 | F30: 카카오웹툰 | G30: 블러디 체어 | H30: 45083 | I30: 46143 | J30: 24804.9 | K30: 0.6 | L30: 14883 | M30: =VLOOKUP(G:G,list!B:E,4,FALSE) -> - | N30: =ROUND(IF(M30="-",0,L30*M30),0) -> 0 | O30: =L30-N30 -> 14883 | Q30: =VLOOKUP(G:G,list!B:F,5,FALSE) -> - | R30: =VLOOKUP(G:G,list!B:D,3,FALSE) -> N
B31: 26 | C31: =VLOOKUP(G:G,list!B:D,2,FALSE) -> 외부제작 | D31: 국내 | E31: 독점 | F31: 카카오웹툰 | G31: 강호, 미치다! | H31: 45204 | I31: 46143 | J31: 25993.6 | K31: 0.6 | L31: 15597 | M31: =VLOOKUP(G:G,list!B:E,4,FALSE) -> - | N31: =ROUND(IF(M31="-",0,L31*M31),0) -> 0 | O31: =L31-N31 -> 15597 | Q31: =VLOOKUP(G:G,list!B:F,5,FALSE) -> - | R31: =VLOOKUP(G:G,list!B:D,3,FALSE) -> N
B32: 27 | C32: =VLOOKUP(G:G,list!B:D,2,FALSE) -> 원작료 | D32: 국내 | E32: 독점 | F32: 카카오웹툰 | G32: 악녀인데 요리를 너무 잘해 | H32: 45236 | I32: 46143 | J32: 59699.9 | K32: 0.6 | L32: 35821 | M32: =VLOOKUP(G:G,list!B:E,4,FALSE) -> 0.1 | N32: =ROUND(IF(M32="-",0,L32*M32),0) -> 3582 | O32: =L32-N32 -> 32239 | Q32: =VLOOKUP(G:G,list!B:F,5,FALSE) -> - | R32: =VLOOKUP(G:G,list!B:D,3,FALSE) -> N
B33: 28 | C33: =VLOOKUP(G:G,list!B:D,2,FALSE) -> 원작료 | D33: 일본 | E33: 독점 | F33: 픽코마 | G33: 마족의 계약 | H33: 44359 | I33: 46113 | J33: 108811 | K33: 0.224 | L33: 21945 | M33: =VLOOKUP(G:G,list!B:E,4,FALSE) -> 0.1 | N33: =ROUND(IF(M33="-",0,L33*M33),0) -> 2195 | O33: =L33-N33 -> 19750 | Q33: =VLOOKUP(G:G,list!B:F,5,FALSE) -> 웹소설본부 | R33: =VLOOKUP(G:G,list!B:D,3,FALSE) -> Y
B34: 29 | C34: =VLOOKUP(G:G,list!B:D,2,FALSE) -> 원작료 | D34: 일본 | E34: 독점 | F34: 픽코마 | G34: 악역에게 청혼받았습니다 | H34: 44629 | I34: 46113 | J34: 781046 | K34: 0.224 | L34: 157462 | M34: =VLOOKUP(G:G,list!B:E,4,FALSE) -> 0.1 | N34: =ROUND(IF(M34="-",0,L34*M34),0) -> 15746 | O34: =L34-N34 -> 141716 | Q34: =VLOOKUP(G:G,list!B:F,5,FALSE) -> 웹소설본부 | R34: =VLOOKUP(G:G,list!B:D,3,FALSE) -> Y
B35: 30 | C35: =VLOOKUP(G:G,list!B:D,2,FALSE) -> 작가기획 | D35: 일본 | E35: 독점 | F35: 픽코마 | G35: 별이 빈 소원 | H35: 44773 | I35: 46113 | J35: 0 | K35: 0.224 | L35: 0 | M35: =VLOOKUP(G:G,list!B:E,4,FALSE) -> - | N35: =ROUND(IF(M35="-",0,L35*M35),0) -> 0 | O35: =L35-N35 -> 0 | P35: *매출없음 | Q35: =VLOOKUP(G:G,list!B:F,5,FALSE) -> - | R35: =VLOOKUP(G:G,list!B:D,3,FALSE) -> Y
B36: 31 | C36: =VLOOKUP(G:G,list!B:D,2,FALSE) -> 원작료 | D36: 일본 | E36: 독점 | F36: 픽코마 | G36: 입술 좀 빌려주세요 | H36: 44784 | I36: 46113 | J36: 143562 | K36: 0.224 | L36: 28945 | M36: =VLOOKUP(G:G,list!B:E,4,FALSE) -> 0.1 | N36: =ROUND(IF(M36="-",0,L36*M36),0) -> 2895 | O36: =L36-N36 -> 26050 | Q36: =VLOOKUP(G:G,list!B:F,5,FALSE) -> 웹소설본부 | R36: =VLOOKUP(G:G,list!B:D,3,FALSE) -> Y
B37: 32 | C37: =VLOOKUP(G:G,list!B:D,2,FALSE) -> 원작료 | D37: 일본 | E37: 독점 | F37: 픽코마 | G37: 만렙으로 사는 법 | H37: 44808 | I37: 46113 | J37: 31902 | K37: 0.224 | L37: 6436 | M37: =VLOOKUP(G:G,list!B:E,4,FALSE) -> 0.11 | N37: =ROUND(IF(M37="-",0,L37*M37),0) -> 708 | O37: =L37-N37 -> 5728 | Q37: =VLOOKUP(G:G,list!B:F,5,FALSE) -> - | R37: =VLOOKUP(G:G,list!B:D,3,FALSE) -> N
B38: 33 | C38: =VLOOKUP(G:G,list!B:D,2,FALSE) -> 원작료 | D38: 일본 | E38: 독점 | F38: 픽코마 | G38: 악녀인데 남주를 주워버렸다 | H38: 44813 | I38: 46113 | J38: 104823 | K38: 0.224 | L38: 21136 | M38: =VLOOKUP(G:G,list!B:E,4,FALSE) -> 0.1 | N38: =ROUND(IF(M38="-",0,L38*M38),0) -> 2114 | O38: =L38-N38 -> 19022 | Q38: =VLOOKUP(G:G,list!B:F,5,FALSE) -> 웹소설본부 | R38: =VLOOKUP(G:G,list!B:D,3,FALSE) -> Y
B39: 34 | C39: =VLOOKUP(G:G,list!B:D,2,FALSE) -> 외부제작 | D39: 일본 | E39: 독점 | F39: 픽코마 | G39: 블러디 체어 | H39: 44825 | I39: 46113 | J39: 55829 | K39: 0.224 | L39: 11263 | M39: =VLOOKUP(G:G,list!B:E,4,FALSE) -> - | N39: =ROUND(IF(M39="-",0,L39*M39),0) -> 0 | O39: =L39-N39 -> 11263 | Q39: =VLOOKUP(G:G,list!B:F,5,FALSE) -> - | R39: =VLOOKUP(G:G,list!B:D,3,FALSE) -> N
B40: 35 | C40: =VLOOKUP(G:G,list!B:D,2,FALSE) -> 원작료 | D40: 일본 | E40: 독점 | F40: 픽코마 | G40: 책만 보고 탑배우! | H40: 45035 | I40: 46113 | J40: 1594565 | K40: 0.224 | L40: 321469 | M40: =VLOOKUP(G:G,list!B:E,4,FALSE) -> 0.1 | N40: =ROUND(IF(M40="-",0,L40*M40),0) -> 32147 | O40: =L40-N40 -> 289322 | Q40: =VLOOKUP(G:G,list!B:F,5,FALSE) -> - | R40: =VLOOKUP(G:G,list!B:D,3,FALSE) -> Y
B41: 36 | C41: =VLOOKUP(G:G,list!B:D,2,FALSE) -> 작가기획 | D41: 일본 | E41: 독점 | F41: 픽코마 | G41: 너를 만지면 | H41: 45116 | I41: 46113 | J41: 0 | K41: 0.224 | L41: 0 | M41: =VLOOKUP(G:G,list!B:E,4,FALSE) -> - | N41: =ROUND(IF(M41="-",0,L41*M41),0) -> 0 | O41: =L41-N41 -> 0 | P41: *매출없음 | Q41: =VLOOKUP(G:G,list!B:F,5,FALSE) -> - | R41: =VLOOKUP(G:G,list!B:D,3,FALSE) -> N
...

Sheet 26.06
B2: 2026.06월 (매입) 지급 대상 유통 정산 금액 & 정산 순매출
B3: - 수성 입금 기간 : 2026.05.01~2026.05.31
I4: 합계 | J4: =SUBTOTAL(109,J6:J1048576) -> 14422763 | L4: =SUBTOTAL(109,L6:L1048576) -> 5265506 | N4: =SUBTOTAL(109,N6:N1048576) -> 452517 | O4: =SUBTOTAL(109,O6:O1048576) -> 4812989
B5: NO | C5: 항목 | D5: 판매 국가 | E5: 구분 (독/비독) | F5: 플랫폼명 | G5: 작품명 | H5: 런칭일 | I5: 서비스월 (=판매월) | J5: 총매출(A) (요약본 정산기준매출) | K5: RS율 (테라핀) | L5: 정산기준매출(B) (테라핀) | M5: RS율 (원작사) | N5: 원작료(C) (B×원작사 RS율) | O5: 정산순매출 (B－C) | P5: 비고1 | Q5: 웹소설본부 원작여부 | R5: RS 대상여부 (외주작가)
B6: 1 | C6: =VLOOKUP(G:G,list!B:D,2,FALSE) -> 외부제작 | D6: 국내 | E6: 독점 | F6: 카카오페이지_앙상블 | G6: 블러디 체어 | H6: 44629 | I6: 46113 | J6: 190734.6 | K6: 0.6 | L6: 114440 | M6: =VLOOKUP(G:G,list!B:E,4,FALSE) -> - | N6: =ROUND(IF(M6="-",0,L6*M6),0) -> 0 | O6: =L6-N6 -> 114440 | Q6: =VLOOKUP(G:G,list!B:F,5,FALSE) -> - | R6: =VLOOKUP(G:G,list!B:D,3,FALSE) -> N
B7: 2 | C7: =VLOOKUP(G:G,list!B:D,2,FALSE) -> 외부제작 | D7: 국내 | E7: 독점 | F7: 카카오페이지_앙상블 | G7: 검신 | H7: 45057 | I7: 46113 | J7: 84180 | K7: 0.6 | L7: 50507 | M7: =VLOOKUP(G:G,list!B:E,4,FALSE) -> - | N7: =ROUND(IF(M7="-",0,L7*M7),0) -> 0 | O7: =L7-N7 -> 50507 | Q7: =VLOOKUP(G:G,list!B:F,5,FALSE) -> - | R7: =VLOOKUP(G:G,list!B:D,3,FALSE) -> N
B8: 3 | C8: =VLOOKUP(G:G,list!B:D,2,FALSE) -> 외부제작 | D8: 국내 | E8: 독점 | F8: 카카오페이지_앙상블 | G8: 강호, 미치다! | H8: 45204 | I8: 46113 | J8: 170705 | K8: 0.6 | L8: 102424 | M8: =VLOOKUP(G:G,list!B:E,4,FALSE) -> - | N8: =ROUND(IF(M8="-",0,L8*M8),0) -> 0 | O8: =L8-N8 -> 102424 | Q8: =VLOOKUP(G:G,list!B:F,5,FALSE) -> - | R8: =VLOOKUP(G:G,list!B:D,3,FALSE) -> N
B9: 4 | C9: =VLOOKUP(G:G,list!B:D,2,FALSE) -> 원작료 | D9: 국내 | E9: 독점 | F9: 카카오페이지 | G9: 마족의 계약 | H9: 44199 | I9: 46113 | J9: 72916 | K9: 0.6 | L9: 43749 | M9: =VLOOKUP(G:G,list!B:E,4,FALSE) -> 0.1 | N9: =ROUND(IF(M9="-",0,L9*M9),0) -> 4375 | O9: =L9-N9 -> 39374 | Q9: =VLOOKUP(G:G,list!B:F,5,FALSE) -> 웹소설본부 | R9: =VLOOKUP(G:G,list!B:D,3,FALSE) -> Y
B10: 5 | C10: =VLOOKUP(G:G,list!B:D,2,FALSE) -> 원작료 | D10: 국내 | E10: 독점 | F10: 카카오페이지 | G10: 악역에게 청혼받았습니다 | H10: 44372 | I10: 46113 | J10: 42500.9 | K10: 0.6 | L10: 25499 | M10: =VLOOKUP(G:G,list!B:E,4,FALSE) -> 0.1 | N10: =ROUND(IF(M10="-",0,L10*M10),0) -> 2550 | O10: =L10-N10 -> 22949 | Q10: =VLOOKUP(G:G,list!B:F,5,FALSE) -> 웹소설본부 | R10: =VLOOKUP(G:G,list!B:D,3,FALSE) -> Y
B11: 6 | C11: =VLOOKUP(G:G,list!B:D,2,FALSE) -> 작가기획 | D11: 국내 | E11: 독점 | F11: 카카오페이지 | G11: 별이 빈 소원 | H11: 44608 | I11: 46113 | J11: -1552 | K11: 0.6 | L11: -931 | M11: =VLOOKUP(G:G,list!B:E,4,FALSE) -> - | N11: =ROUND(IF(M11="-",0,L11*M11),0) -> 0 | O11: =L11-N11 -> -931 | Q11: =VLOOKUP(G:G,list!B:F,5,FALSE) -> - | R11: =VLOOKUP(G:G,list!B:D,3,FALSE) -> Y
B12: 7 | C12: =VLOOKUP(G:G,list!B:D,2,FALSE) -> 원작료 | D12: 국내 | E12: 독점 | F12: 카카오페이지 | G12: 입술 좀 빌려주세요 | H12: 44639 | I12: 46113 | J12: 120759.1 | K12: 0.6 | L12: 72455 | M12: =VLOOKUP(G:G,list!B:E,4,FALSE) -> 0.1 | N12: =ROUND(IF(M12="-",0,L12*M12),0) -> 7246 | O12: =L12-N12 -> 65209 | Q12: =VLOOKUP(G:G,list!B:F,5,FALSE) -> 웹소설본부 | R12: =VLOOKUP(G:G,list!B:D,3,FALSE) -> Y
B13: 8 | C13: =VLOOKUP(G:G,list!B:D,2,FALSE) -> 원작료 | D13: 국내 | E13: 독점 | F13: 카카오페이지 | G13: 악녀인데 남주를 주워버렸다 | H13: 44691 | I13: 46113 | J13: 38513 | K13: 0.6 | L13: 23108 | M13: =VLOOKUP(G:G,list!B:E,4,FALSE) -> 0.1 | N13: =ROUND(IF(M13="-",0,L13*M13),0) -> 2311 | O13: =L13-N13 -> 20797 | Q13: =VLOOKUP(G:G,list!B:F,5,FALSE) -> 웹소설본부 | R13: =VLOOKUP(G:G,list!B:D,3,FALSE) -> Y
B14: 9 | C14: =VLOOKUP(G:G,list!B:D,2,FALSE) -> 원작료 | D14: 국내 | E14: 독점 | F14: 카카오페이지 | G14: 만렙으로 사는 법 | H14: 44709 | I14: 46113 | J14: 119960 | K14: 0.6 | L14: 71975 | M14: =VLOOKUP(G:G,list!B:E,4,FALSE) -> 0.11 | N14: =ROUND(IF(M14="-",0,L14*M14),0) -> 7917 | O14: =L14-N14 -> 64058 | Q14: =VLOOKUP(G:G,list!B:F,5,FALSE) -> - | R14: =VLOOKUP(G:G,list!B:D,3,FALSE) -> N
B15: 10 | C15: =VLOOKUP(G:G,list!B:D,2,FALSE) -> 원작료 | D15: 국내 | E15: 독점 | F15: 카카오페이지 | G15: 책만 보고 탑배우! | H15: 44801 | I15: 46113 | J15: 169406.8 | K15: 0.6 | L15: 101644 | M15: =VLOOKUP(G:G,list!B:E,4,FALSE) -> 0.1 | N15: =ROUND(IF(M15="-",0,L15*M15),0) -> 10164 | O15: =L15-N15 -> 91480 | Q15: =VLOOKUP(G:G,list!B:F,5,FALSE) -> - | R15: =VLOOKUP(G:G,list!B:D,3,FALSE) -> Y
B16: 11 | C16: =VLOOKUP(G:G,list!B:D,2,FALSE) -> 원작료 | D16: 국내 | E16: 독점 | F16: 카카오페이지 | G16: 그 남자, 처음, 로맨틱 | H16: 44831 | I16: 46113 | J16: 13946 | K16: 0.6 | L16: 8368 | M16: =VLOOKUP(G:G,list!B:E,4,FALSE) -> 0.1 | N16: =ROUND(IF(M16="-",0,L16*M16),0) -> 837 | O16: =L16-N16 -> 7531 | Q16: =VLOOKUP(G:G,list!B:F,5,FALSE) -> 웹소설본부 | R16: =VLOOKUP(G:G,list!B:D,3,FALSE) -> Y
B17: 12 | C17: =VLOOKUP(G:G,list!B:D,2,FALSE) -> 작가기획 | D17: 국내 | E17: 독점 | F17: 카카오페이지 | G17: 너를 만지면 | H17: 44851 | I17: 46113 | J17: 1274 | K17: 0.7 | L17: 892 | M17: =VLOOKUP(G:G,list!B:E,4,FALSE) -> - | N17: =ROUND(IF(M17="-",0,L17*M17),0) -> 0 | O17: =L17-N17 -> 892 | Q17: =VLOOKUP(G:G,list!B:F,5,FALSE) -> - | R17: =VLOOKUP(G:G,list!B:D,3,FALSE) -> N
... B22: 17 | C22: =VLOOKUP(G:G,list!B:D,2,FALSE) -> 원작료 | D22: 국내 | E22: 독점 | F22: 카카오웹툰 | G22: 입술 좀 빌려주세요 | H22: 44926 | I22: 46113 | J22: 59072.8 | K22: 0.6 | L22: 35444 | M22: =VLOOKUP(G:G,list!B:E,4,FALSE) -> 0.1 | N22: =ROUND(IF(M22="-",0,L22*M22),0) -> 3544 | O22: =L22-N22 -> 31900 | Q22: =VLOOKUP(G:G,list!B:F,5,FALSE) -> 웹소설본부 | R22: =VLOOKUP(G:G,list!B:D,3,FALSE) -> Y
B23: 18 | C23: =VLOOKUP(G:G,list!B:D,2,FALSE) -> 작가기획 | D23: 국내 | E23: 독점 | F23: 카카오웹툰 | G23: 별이 빈 소원 | H23: 44944 | I23: 46113 | J23: 0 | K23: 0.6 | L23: 0 | M23: =VLOOKUP(G:G,list!B:E,4,FALSE) -> - | N23: =ROUND(IF(M23="-",0,L23*M23),0) -> 0 | O23: =L23-N23 -> 0 | P23: *매출없음 | Q23: =VLOOKUP(G:G,list!B:F,5,FALSE) -> - | R23: =VLOOKUP(G:G,list!B:D,3,FALSE) -> Y
B24: 19 | C24: =VLOOKUP(G:G,list!B:D,2,FALSE) -> 원작료 | D24: 국내 | E24: 독점 | F24: 카카오웹툰 | G24: 책만 보고 탑배우! | H24: 44969 | I24: 46113 | J24: 37056.9 | K24: 0.6 | L24: 22234 | M24: =VLOOKUP(G:G,list!B:E,4,FALSE) -> 0.1 | N24: =ROUND(IF(M24="-",0,L24*M24),0) -> 2223 | O24: =L24-N24 -> 20011 | Q24: =VLOOKUP(G:G,list!B:F,5,FALSE) -> - | R24: =VLOOKUP(G:G,list!B:D,3,FALSE) -> Y
B25: 20 | C25: =VLOOKUP(G:G,list!B:D,2,FALSE) -> 원작료 | D25: 국내 | E25: 독점 | F25: 카카오웹툰 | G25: 그 남자, 처음, 로맨틱 | H25: 44981 | I25: 46113 | J25: 9396 | K25: 0.6 | L25: 5637 | M25: =VLOOKUP(G:G,list!B:E,4,FALSE) -> 0.1 | N25: =ROUND(IF(M25="-",0,L25*M25),0) -> 564 | O25: =L25-N25 -> 5073 | Q25: =VLOOKUP(G:G,list!B:F,5,FALSE) -> 웹소설본부 | R25: =VLOOKUP(G:G,list!B:D,3,FALSE) -> Y
B26: 21 | C26: =VLOOKUP(G:G,list!B:D,2,FALSE) -> 원작료 | D26: 국내 | E26: 독점 | F26: 카카오웹툰 | G26: 악역에게 청혼받았습니다 | H26: 44988 | I26: 46113 | J26: 41398.6 | K26: 0.6 | L26: 24840 | M26: =VLOOKUP(G:G,list!B:E,4,FALSE) -> 0.1 | N26: =ROUND(IF(M26="-",0,L26*M26),0) -> 2484 | O26: =L26-N26 -> 22356 | Q26: =VLOOKUP(G:G,list!B:F,5,FALSE) -> 웹소설본부 | R26: =VLOOKUP(G:G,list!B:D,3,FALSE) -> Y
B27: 22 | C27: =VLOOKUP(G:G,list!B:D,2,FALSE) -> 원작료 | D27: 국내 | E27: 독점 | F27: 카카오웹툰 | G27: 악녀인데 남주를 주워버렸다 | H27: 45033 | I27: 46113 | J27: 22514.7 | K27: 0.6 | L27: 13509 | M27: =VLOOKUP(G:G,list!B:E,4,FALSE) -> 0.1 | N27: =ROUND(IF(M27="-",0,L27*M27),0) -> 1351 | O27: =L27-N27 -> 12158 | Q27: =VLOOKUP(G:G,list!B:F,5,FALSE) -> 웹소설본부 | R27: =VLOOKUP(G:G,list!B:D,3,FALSE) -> Y
B28: 23 | C28: =VLOOKUP(G:G,list!B:D,2,FALSE) -> 외부제작 | D28: 국내 | E28: 독점 | F28: 카카오웹툰 | G28: 검신 | H28: 45057 | I28: 46113 | J28: 13788 | K28: 0.6 | L28: 8273 | M28: =VLOOKUP(G:G,list!B:E,4,FALSE) -> - | N28: =ROUND(IF(M28="-",0,L28*M28),0) -> 0 | O28: =L28-N28 -> 8273 | Q28: =VLOOKUP(G:G,list!B:F,5,FALSE) -> - | R28: =VLOOKUP(G:G,list!B:D,3,FALSE) -> N
B29: 24 | C29: =VLOOKUP(G:G,list!B:D,2,FALSE) -> 원작료 | D29: 국내 | E29: 독점 | F29: 카카오웹툰 | G29: 만렙으로 사는 법 | H29: 45057 | I29: 46113 | J29: 6717 | K29: 0.6 | L29: 4031 | M29: =VLOOKUP(G:G,list!B:E,4,FALSE) -> 0.11 | N29: =ROUND(IF(M29="-",0,L29*M29),0) -> 443 | O29: =L29-N29 -> 3588 | Q29: =VLOOKUP(G:G,list!B:F,5,FALSE) -> - | R29: =VLOOKUP(G:G,list!B:D,3,FALSE) -> N
B30: 25 | C30: =VLOOKUP(G:G,list!B:D,2,FALSE) -> 외부제작 | D30: 국내 | E30: 독점 | F30: 카카오웹툰 | G30: 블러디 체어 | H30: 45083 | I30: 46113 | J30: 61537.9 | K30: 0.6 | L30: 36922 | M30: =VLOOKUP(G:G,list!B:E,4,FALSE) -> - | N30: =ROUND(IF(M30="-",0,L30*M30),0) -> 0 | O30: =L30-N30 -> 36922 | Q30: =VLOOKUP(G:G,list!B:F,5,FALSE) -> - | R30: =VLOOKUP(G:G,list!B:D,3,FALSE) -> N
B31: 26 | C31: =VLOOKUP(G:G,list!B:D,2,FALSE) -> 외부제작 | D31: 국내 | E31: 독점 | F31: 카카오웹툰 | G31: 강호, 미치다! | H31: 45204 | I31: 46113 | J31: 59918.9 | K31: 0.6 | L31: 35952 | M31: =VLOOKUP(G:G,list!B:E,4,FALSE) -> - | N31: =ROUND(IF(M31="-",0,L31*M31),0) -> 0 | O31: =L31-N31 -> 35952 | Q31: =VLOOKUP(G:G,list!B:F,5,FALSE) -> - | R31: =VLOOKUP(G:G,list!B:D,3,FALSE) -> N
B32: 27 | C32: =VLOOKUP(G:G,list!B:D,2,FALSE) -> 원작료 | D32: 국내 | E32: 독점 | F32: 카카오웹툰 | G32: 악녀인데 요리를 너무 잘해 | H32: 45236 | I32: 46113 | J32: 119920.8 | K32: 0.6 | L32: 71953 | M32: =VLOOKUP(G:G,list!B:E,4,FALSE) -> 0.1 | N32: =ROUND(IF(M32="-",0,L32*M32),0) -> 7195 | O32: =L32-N32 -> 64758 | Q32: =VLOOKUP(G:G,list!B:F,5,FALSE) -> - | R32: =VLOOKUP(G:G,list!B:D,3,FALSE) -> N
B33: 28 | C33: =VLOOKUP(G:G,list!B:D,2,FALSE) -> 원작료 | D33: 일본 | E33: 독점 | F33: 픽코마 | G33: 마족의 계약 | H33: 44359 | I33: 46082 | J33: 115989 | K33: 0.224 | L33: 23386 | M33: =VLOOKUP(G:G,list!B:E,4,FALSE) -> 0.1 | N33: =ROUND(IF(M33="-",0,L33*M33),0) -> 2339 | O33: =L33-N33 -> 21047 | Q33: =VLOOKUP(G:G,list!B:F,5,FALSE) -> 웹소설본부 | R33: =VLOOKUP(G:G,list!B:D,3,FALSE) -> Y
B34: 29 | C34: =VLOOKUP(G:G,list!B:D,2,FALSE) -> 원작료 | D34: 일본 | E34: 독점 | F34: 픽코마 | G34: 악역에게 청혼받았습니다 | H34: 44629 | I34: 46082 | J34: 386249 | K34: 0.224 | L34: 77874 | M34: =VLOOKUP(G:G,list!B:E,4,FALSE) -> 0.1 | N34: =ROUND(IF(M34="-",0,L34*M34),0) -> 7787 | O34: =L34-N34 -> 70087 | Q34: =VLOOKUP(G:G,list!B:F,5,FALSE) -> 웹소설본부 | R34: =VLOOKUP(G:G,list!B:D,3,FALSE) -> Y
B35: 30 | C35: =VLOOKUP(G:G,list!B:D,2,FALSE) -> 작가기획 | D35: 일본 | E35: 독점 | F35: 픽코마 | G35: 별이 빈 소원 | H35: 44773 | I35: 46082 | J35: 0 | K35: 0.224 | L35: 0 | M35: =VLOOKUP(G:G,list!B:E,4,FALSE) -> - | N35: =ROUND(IF(M35="-",0,L35*M35),0) -> 0 | O35: =L35-N35 -> 0 | P35: *매출없음 | Q35: =VLOOKUP(G:G,list!B:F,5,FALSE) -> - | R35: =VLOOKUP(G:G,list!B:D,3,FALSE) -> Y
B36: 31 | C36: =VLOOKUP(G:G,list!B:D,2,FALSE) -> 원작료 | D36: 일본 | E36: 독점 | F36: 픽코마 | G36: 입술 좀 빌려주세요 | H36: 44784 | I36: 46082 | J36: 53137 | K36: 0.224 | L36: 10713 | M36: =VLOOKUP(G:G,list!B:E,4,FALSE) -> 0.1 | N36: =ROUND(IF(M36="-",0,L36*M36),0) -> 1071 | O36: =L36-N36 -> 9642 | Q36: =VLOOKUP(G:G,list!B:F,5,FALSE) -> 웹소설본부 | R36: =VLOOKUP(G:G,list!B:D,3,FALSE) -> Y
B37: 32 | C37: =VLOOKUP(G:G,list!B:D,2,FALSE) -> 원작료 | D37: 일본 | E37: 독점 | F37: 픽코마 | G37: 만렙으로 사는 법 | H37: 44808 | I37: 46082 | J37: 347967 | K37: 0.224 | L37: 70151 | M37: =VLOOKUP(G:G,list!B:E,4,FALSE) -> 0.11 | N37: =ROUND(IF(M37="-",0,L37*M37),0) -> 7717 | O37: =L37-N37 -> 62434 | Q37: =VLOOKUP(G:G,list!B:F,5,FALSE) -> - | R37: =VLOOKUP(G:G,list!B:D,3,FALSE) -> N
B38: 33 | C38: =VLOOKUP(G:G,list!B:D,2,FALSE) -> 원작료 | D38: 일본 | E38: 독점 | F38: 픽코마 | G38: 악녀인데 남주를 주워버렸다 | H38: 44813 | I38: 46082 | J38: 102276 | K38: 0.224 | L38: 20624 | M38: =VLOOKUP(G:G,list!B:E,4,FALSE) -> 0.1 | N38: =ROUND(IF(M38="-",0,L38*M38),0) -> 2062 | O38: =L38-N38 -> 18562 | Q38: =VLOOKUP(G:G,list!B:F,5,FALSE) -> 웹소설본부 | R38: =VLOOKUP(G:G,list!B:D,3,FALSE) -> Y
B39: 34 | C39: =VLOOKUP(G:G,list!B:D,2,FALSE) -> 외부제작 | D39: 일본 | E39: 독점 | F39: 픽코마 | G39: 블러디 체어 | H39: 44825 | I39: 46082 | J39: 42281 | K39: 0.224 | L39: 8525 | M39: =VLOOKUP(G:G,list!B:E,4,FALSE) -> - | N39: =ROUND(IF(M39="-",0,L39*M39),0) -> 0 | O39: =L39-N39 -> 8525 | Q39: =VLOOKUP(G:G,list!B:F,5,FALSE) -> - | R39: =VLOOKUP(G:G,list!B:D,3,FALSE) -> N
B40: 35 | C40: =VLOOKUP(G:G,list!B:D,2,FALSE) -> 원작료 | D40: 일본 | E40: 독점 | F40: 픽코마 | G40: 책만 보고 탑배우! | H40: 45035 | I40: 46082 | J40: 2204363 | K40: 0.224 | L40: 444405 | M40: =VLOOKUP(G:G,list!B:E,4,FALSE) -> 0.1 | N40: =ROUND(IF(M40="-",0,L40*M40),0) -> 44441 | O40: =L40-N40 -> 399964 | Q40: =VLOOKUP(G:G,list!B:F,5,FALSE) -> - | R40: =VLOOKUP(G:G,list!B:D,3,FALSE) -> Y
B41: 36 | C41: =VLOOKUP(G:G,list!B:D,2,FALSE) -> 작가기획 | D41: 일본 | E41: 독점 | F41: 픽코마 | G41: 너를 만지면 | H41: 45116 | I41: 46082 | J41: 0 | K41: 0.224 | L41: 0 | M41: =VLOOKUP(G:G,list!B:E,4,FALSE) -> - | N41: =ROUND(IF(M41="-",0,L41*M41),0) -> 0 | O41: =L41-N41 -> 0 | P41: *매출없음 | Q41: =VLOOKUP(G:G,list!B:F,5,FALSE) -> - | R41: =VLOOKUP(G:G,list!B:D,3,FALSE) -> N
B42: 37 | C42: =VLOOKUP(G:G,list!B:D,2,FALSE) -> 원작료 | D42: 일본 | E42: 독점 | F42: 픽코마 | G42: 그 남자, 처음, 로맨틱 | H42: 45237 | I42: 46082 | J42: 94848 | K42: 0.224 | L42: 19129 | M42: =VLOOKUP(G:G,list!B:E,4,FALSE) -> 0.1 | N42: =ROUND(IF(M42="-",0,L42*M42),0) -> 1913 | O42: =L42-N42 -> 17216 | Q42: =VLOOKUP(G:G,list!B:F,5,FALSE) -> 웹소설본부 | R42: =VLOOKUP(G:G,list!B:D,3,FALSE) -> Y
B43: 38 | C43: =VLOOKUP(G:G,list!B:D,2,FALSE) -> 원작료 | D43: 일본 | E43: 독점 | F43: 픽코마 | G43: 악녀인데 요리를 너무 잘해 | H43: 45364 | I43: 46082 | J43: 1270166 | K43: 0.224 | L43: 256070 | M43: =VLOOKUP(G:G,list!B:E,4,FALSE) -> 0.1 | N43: =ROUND(IF(M43="-",0,L43*M43),0) -> 25607 | O43: =L43-N43 -> 230463 | Q43: =VLOOKUP(G:G,list!B:F,5,FALSE) -> - | R43: =VLOOKUP(G:G,list!B:D,3,FALSE) -> N
B44: 39 | C44: =VLOOKUP(G:G,list!B:D,2,FALSE) -> 외부제작 | D44: 일본 | E44: 독점 | F44: 픽코마 | G44: 강호, 미치다! | H44: 45412 | I44: 46082 | J44: 280545 | K44: 0.224 | L44: 56566 | M44: =VLOOKUP(G:G,list!B:E,4,FALSE) -> - | N44: =ROUND(IF(M44="-",0,L44*M44),0) -> 0 | O44: =L44-N44 -> 56566 | Q44: =VLOOKUP(G:G,list!B:F,5,FALSE) -> - | R44: =VLOOKUP(G:G,list!B:D,3,FALSE) -> N
B45: 40 | C45: =VLOOKUP(G:G,list!B:D,2,FALSE) -> 원작료 | D45: 태국 | E45: 독점 | F45: 카카오페이지 | G45: 악녀인데 남주를 주워버렸다 | H45: 45901 | I45: 46113 | J45: 0 | K45: 0.35 | L45: 0 | M45: =VLOOKUP(G:G,list!B:E,4,FALSE) -> 0.1 | N45: =ROUND(IF(M45="-",0,L45*M45),0) -> 0 | O45: =L45-N45 -> 0 | P45: *매출없음 | Q45: =VLOOKUP(G:G,list!B:F,5,FALSE) -> 웹소설본부 | R45: =VLOOKUP(G:G,list!B:D,3,FALSE) -> Y
...

Sheet 26.05
B2: 2026.05월 (매입) 지급 대상 유통 정산 금액 & 정산 순매출
B3: - 수성 입금 기간 : 2026.04.01~2026.04.30
I4: 합계 | J4: =SUBTOTAL(109,J6:J1048576) -> 14717858 | L4: =SUBTOTAL(109,L6:L1048576) -> 5931767.5 | N4: =SUBTOTAL(109,N6:N1048576) -> 526620 | O4: =SUBTOTAL(109,O6:O1048576) -> 5405147.5
B5: NO | C5: 항목 | D5: 판매 국가 | E5: 구분 (독/비독) | F5: 플랫폼명 | G5: 작품명 | H5: 런칭일 | I5: 서비스월 (=판매월) | J5: 총매출(A) (요약본 정산기준매출) | K5: RS율 (테라핀) | L5: 정산기준매출(B) (테라핀) | M5: RS율 (원작사) | N5: 원작료(C) (B×원작사 RS율) | O5: 정산순매출 (B－C) | P5: 비고1 | Q5: 웹소설본부 원작여부 | R5: RS 대상여부 (외주작가)
B6: 1 | C6: =VLOOKUP(G:G,list!B:D,2,FALSE) -> 외부제작 | D6: 국내 | E6: 독점 | F6: 카카오페이지_앙상블 | G6: 블러디 체어 | H6: 44629 | I6: 46082 | J6: 165185 | K6: 0.6 | L6: 99111 | M6: =VLOOKUP(G:G,list!B:E,4,FALSE) -> - | N6: =ROUND(IF(M6="-",0,L6*M6),0) -> 0 | O6: =L6-N6 -> 99111 | Q6: =VLOOKUP(G:G,list!B:F,5,FALSE) -> - | R6: =VLOOKUP(G:G,list!B:D,3,FALSE) -> N
B7: 2 | C7: =VLOOKUP(G:G,list!B:D,2,FALSE) -> 외부제작 | D7: 국내 | E7: 독점 | F7: 카카오페이지_앙상블 | G7: 검신 | H7: 45057 | I7: 46082 | J7: 83177 | K7: 0.6 | L7: 49907 | M7: =VLOOKUP(G:G,list!B:E,4,FALSE) -> - | N7: =ROUND(IF(M7="-",0,L7*M7),0) -> 0 | O7: =L7-N7 -> 49907 | Q7: =VLOOKUP(G:G,list!B:F,5,FALSE) -> - | R7: =VLOOKUP(G:G,list!B:D,3,FALSE) -> N
B8: 3 | C8: =VLOOKUP(G:G,list!B:D,2,FALSE) -> 외부제작 | D8: 국내 | E8: 독점 | F8: 카카오페이지_앙상블 | G8: 강호, 미치다! | H8: 45204 | I8: 46082 | J8: 122851 | K8: 0.6 | L8: 73711 | M8: =VLOOKUP(G:G,list!B:E,4,FALSE) -> - | N8: =ROUND(IF(M8="-",0,L8*M8),0) -> 0 | O8: =L8-N8 -> 73711 | Q8: =VLOOKUP(G:G,list!B:F,5,FALSE) -> - | R8: =VLOOKUP(G:G,list!B:D,3,FALSE) -> N
B9: 4 | C9: =VLOOKUP(G:G,list!B:D,2,FALSE) -> 원작료 | D9: 국내 | E9: 독점 | F9: 카카오페이지 | G9: 마족의 계약 | H9: 44199 | I9: 46082 | J9: 105046.3 | K9: 0.6 | L9: 63027 | M9: =VLOOKUP(G:G,list!B:E,4,FALSE) -> 0.1 | N9: =ROUND(IF(M9="-",0,L9*M9),0) -> 6303 | O9: =L9-N9 -> 56724 | Q9: =VLOOKUP(G:G,list!B:F,5,FALSE) -> 웹소설본부 | R9: =VLOOKUP(G:G,list!B:D,3,FALSE) -> Y
B10: 5 | C10: =VLOOKUP(G:G,list!B:D,2,FALSE) -> 원작료 | D10: 국내 | E10: 독점 | F10: 카카오페이지 | G10: 악역에게 청혼받았습니다 | H10: 44372 | I10: 46082 | J10: 727681.3 | K10: 0.6 | L10: 436608 | M10: =VLOOKUP(G:G,list!B:E,4,FALSE) -> 0.1 | N10: =ROUND(IF(M10="-",0,L10*M10),0) -> 43661 | O10: =L10-N10 -> 392947 | Q10: =VLOOKUP(G:G,list!B:F,5,FALSE) -> 웹소설본부 | R10: =VLOOKUP(G:G,list!B:D,3,FALSE) -> Y
B11: 6 | C11: =VLOOKUP(G:G,list!B:D,2,FALSE) -> 작가기획 | D11: 국내 | E11: 독점 | F11: 카카오페이지 | G11: 별이 빈 소원 | H11: 44608 | I11: 46082 | J11: 10441 | K11: 0.6 | L11: 6265 | M11: =VLOOKUP(G:G,list!B:E,4,FALSE) -> - | N11: =ROUND(IF(M11="-",0,L11*M11),0) -> 0 | O11: =L11-N11 -> 6265 | Q11: =VLOOKUP(G:G,list!B:F,5,FALSE) -> - | R11: =VLOOKUP(G:G,list!B:D,3,FALSE) -> Y
B12: 7 | C12: =VLOOKUP(G:G,list!B:D,2,FALSE) -> 원작료 | D12: 국내 | E12: 독점 | F12: 카카오페이지 | G12: 입술 좀 빌려주세요 | H12: 44639 | I12: 46082 | J12: 119693 | K12: 0.6 | L12: 71816 | M12: =VLOOKUP(G:G,list!B:E,4,FALSE) -> 0.1 | N12: =ROUND(IF(M12="-",0,L12*M12),0) -> 7182 | O12: =L12-N12 -> 64634 | Q12: =VLOOKUP(G:G,list!B:F,5,FALSE) -> 웹소설본부 | R12: =VLOOKUP(G:G,list!B:D,3,FALSE) -> Y
B13: 8 | C13: =VLOOKUP(G:G,list!B:D,2,FALSE) -> 원작료 | D13: 국내 | E13: 독점 | F13: 카카오페이지 | G13: 악녀인데 남주를 주워버렸다 | H13: 44691 | I13: 46082 | J13: 22958 | K13: 0.6 | L13: 13774 | M13: =VLOOKUP(G:G,list!B:E,4,FALSE) -> 0.1 | N13: =ROUND(IF(M13="-",0,L13*M13),0) -> 1377 | O13: =L13-N13 -> 12397 | Q13: =VLOOKUP(G:G,list!B:F,5,FALSE) -> 웹소설본부 | R13: =VLOOKUP(G:G,list!B:D,3,FALSE) -> Y
B14: 9 | C14: =VLOOKUP(G:G,list!B:D,2,FALSE) -> 원작료 | D14: 국내 | E14: 독점 | F14: 카카오페이지 | G14: 만렙으로 사는 법 | H14: 44709 | I14: 46082 | J14: 22190 | K14: 0.6 | L14: 13315 | M14: =VLOOKUP(G:G,list!B:E,4,FALSE) -> 0.11 | N14: =ROUND(IF(M14="-",0,L14*M14),0) -> 1465 | O14: =L14-N14 -> 11850 | Q14: =VLOOKUP(G:G,list!B:F,5,FALSE) -> - | R14: =VLOOKUP(G:G,list!B:D,3,FALSE) -> N
B15: 10 | C15: =VLOOKUP(G:G,list!B:D,2,FALSE) -> 원작료 | D15: 국내 | E15: 독점 | F15: 카카오페이지 | G15: 책만 보고 탑배우! | H15: 44801 | I15: 46082 | J15: 234563 | K15: 0.6 | L15: 140738 | M15: =VLOOKUP(G:G,list!B:E,4,FALSE) -> 0.1 | N15: =ROUND(IF(M15="-",0,L15*M15),0) -> 14074 | O15: =L15-N15 -> 126664 | Q15: =VLOOKUP(G:G,list!B:F,5,FALSE) -> - | R15: =VLOOKUP(G:G,list!B:D,3,FALSE) -> Y
B16: 11 | C16: =VLOOKUP(G:G,list!B:D,2,FALSE) -> 원작료 | D16: 국내 | E16: 독점 | F16: 카카오페이지 | G16: 그 남자, 처음, 로맨틱 | H16: 44831 | I16: 46082 | J16: 29846 | K16: 0.6 | L16: 17909 | M16: =VLOOKUP(G:G,list!B:E,4,FALSE) -> 0.1 | N16: =ROUND(IF(M16="-",0,L16*M16),0) -> 1791 | O16: =L16-N16 -> 16118 | Q16: =VLOOKUP(G:G,list!B:F,5,FALSE) -> 웹소설본부 | R16: =VLOOKUP(G:G,list!B:D,3,FALSE) -> Y
B17: 12 | C17: =VLOOKUP(G:G,list!B:D,2,FALSE) -> 작가기획 | D17: 국내 | E17: 독점 | F17: 카카오페이지 | G17: 너를 만지면 | H17: 44851 | I17: 46082 | J17: 4316 | K17: 0.7 | L17: 3021 | M17: =VLOOKUP(G:G,list!B:E,4,FALSE) -> - | N17: =ROUND(IF(M17="-",0,L17*M17),0) -> 0 | O17: =L17-N17 -> 3021 | Q17: =VLOOKUP(G:G,list!B:F,5,FALSE) -> - | R17: =VLOOKUP(G:G,list!B:D,3,FALSE) -> N
... B22: 17 | C22: =VLOOKUP(G:G,list!B:D,2,FALSE) -> 원작료 | D22: 국내 | E22: 독점 | F22: 카카오웹툰 | G22: 입술 좀 빌려주세요 | H22: 44926 | I22: 46082 | J22: 66464.6 | K22: 0.6 | L22: 39879 | M22: =VLOOKUP(G:G,list!B:E,4,FALSE) -> 0.1 | N22: =ROUND(IF(M22="-",0,L22*M22),0) -> 3988 | O22: =L22-N22 -> 35891 | Q22: =VLOOKUP(G:G,list!B:F,5,FALSE) -> 웹소설본부 | R22: =VLOOKUP(G:G,list!B:D,3,FALSE) -> Y
B23: 18 | C23: =VLOOKUP(G:G,list!B:D,2,FALSE) -> 작가기획 | D23: 국내 | E23: 독점 | F23: 카카오웹툰 | G23: 별이 빈 소원 | H23: 44944 | I23: 46082 | J23: 0 | K23: 0.6 | L23: 0 | M23: =VLOOKUP(G:G,list!B:E,4,FALSE) -> - | N23: =ROUND(IF(M23="-",0,L23*M23),0) -> 0 | O23: =L23-N23 -> 0 | P23: *매출없음 | Q23: =VLOOKUP(G:G,list!B:F,5,FALSE) -> - | R23: =VLOOKUP(G:G,list!B:D,3,FALSE) -> Y
B24: 19 | C24: =VLOOKUP(G:G,list!B:D,2,FALSE) -> 원작료 | D24: 국내 | E24: 독점 | F24: 카카오웹툰 | G24: 책만 보고 탑배우! | H24: 44969 | I24: 46082 | J24: 26826.9 | K24: 0.6 | L24: 16097 | M24: =VLOOKUP(G:G,list!B:E,4,FALSE) -> 0.1 | N24: =ROUND(IF(M24="-",0,L24*M24),0) -> 1610 | O24: =L24-N24 -> 14487 | Q24: =VLOOKUP(G:G,list!B:F,5,FALSE) -> - | R24: =VLOOKUP(G:G,list!B:D,3,FALSE) -> Y
B25: 20 | C25: =VLOOKUP(G:G,list!B:D,2,FALSE) -> 원작료 | D25: 국내 | E25: 독점 | F25: 카카오웹툰 | G25: 그 남자, 처음, 로맨틱 | H25: 44981 | I25: 46082 | J25: 0 | K25: 0.6 | L25: 0 | M25: =VLOOKUP(G:G,list!B:E,4,FALSE) -> 0.1 | N25: =ROUND(IF(M25="-",0,L25*M25),0) -> 0 | O25: =L25-N25 -> 0 | P25: *매출없음 | Q25: =VLOOKUP(G:G,list!B:F,5,FALSE) -> 웹소설본부 | R25: =VLOOKUP(G:G,list!B:D,3,FALSE) -> Y
B26: 21 | C26: =VLOOKUP(G:G,list!B:D,2,FALSE) -> 원작료 | D26: 국내 | E26: 독점 | F26: 카카오웹툰 | G26: 악역에게 청혼받았습니다 | H26: 44988 | I26: 46082 | J26: 64205.8 | K26: 0.6 | L26: 38524 | M26: =VLOOKUP(G:G,list!B:E,4,FALSE) -> 0.1 | N26: =ROUND(IF(M26="-",0,L26*M26),0) -> 3852 | O26: =L26-N26 -> 34672 | Q26: =VLOOKUP(G:G,list!B:F,5,FALSE) -> 웹소설본부 | R26: =VLOOKUP(G:G,list!B:D,3,FALSE) -> Y
B27: 22 | C27: =VLOOKUP(G:G,list!B:D,2,FALSE) -> 원작료 | D27: 국내 | E27: 독점 | F27: 카카오웹툰 | G27: 악녀인데 남주를 주워버렸다 | H27: 45033 | I27: 46082 | J27: 21262.9 | K27: 0.6 | L27: 12758 | M27: =VLOOKUP(G:G,list!B:E,4,FALSE) -> 0.1 | N27: =ROUND(IF(M27="-",0,L27*M27),0) -> 1276 | O27: =L27-N27 -> 11482 | Q27: =VLOOKUP(G:G,list!B:F,5,FALSE) -> 웹소설본부 | R27: =VLOOKUP(G:G,list!B:D,3,FALSE) -> Y
B28: 23 | C28: =VLOOKUP(G:G,list!B:D,2,FALSE) -> 외부제작 | D28: 국내 | E28: 독점 | F28: 카카오웹툰 | G28: 검신 | H28: 45057 | I28: 46082 | J28: 2088 | K28: 0.6 | L28: 1253 | M28: =VLOOKUP(G:G,list!B:E,4,FALSE) -> - | N28: =ROUND(IF(M28="-",0,L28*M28),0) -> 0 | O28: =L28-N28 -> 1253 | Q28: =VLOOKUP(G:G,list!B:F,5,FALSE) -> - | R28: =VLOOKUP(G:G,list!B:D,3,FALSE) -> N
B29: 24 | C29: =VLOOKUP(G:G,list!B:D,2,FALSE) -> 원작료 | D29: 국내 | E29: 독점 | F29: 카카오웹툰 | G29: 만렙으로 사는 법 | H29: 45057 | I29: 46082 | J29: 24354.9 | K29: 0.6 | L29: 14613 | M29: =VLOOKUP(G:G,list!B:E,4,FALSE) -> 0.11 | N29: =ROUND(IF(M29="-",0,L29*M29),0) -> 1607 | O29: =L29-N29 -> 13006 | Q29: =VLOOKUP(G:G,list!B:F,5,FALSE) -> - | R29: =VLOOKUP(G:G,list!B:D,3,FALSE) -> N
B30: 25 | C30: =VLOOKUP(G:G,list!B:D,2,FALSE) -> 외부제작 | D30: 국내 | E30: 독점 | F30: 카카오웹툰 | G30: 블러디 체어 | H30: 45083 | I30: 46082 | J30: 7660 | K30: 0.6 | L30: 4596 | M30: =VLOOKUP(G:G,list!B:E,4,FALSE) -> - | N30: =ROUND(IF(M30="-",0,L30*M30),0) -> 0 | O30: =L30-N30 -> 4596 | Q30: =VLOOKUP(G:G,list!B:F,5,FALSE) -> - | R30: =VLOOKUP(G:G,list!B:D,3,FALSE) -> N
B31: 26 | C31: =VLOOKUP(G:G,list!B:D,2,FALSE) -> 외부제작 | D31: 국내 | E31: 독점 | F31: 카카오웹툰 | G31: 강호, 미치다! | H31: 45204 | I31: 46082 | J31: 19742.9 | K31: 0.6 | L31: 11846 | M31: =VLOOKUP(G:G,list!B:E,4,FALSE) -> - | N31: =ROUND(IF(M31="-",0,L31*M31),0) -> 0 | O31: =L31-N31 -> 11846 | Q31: =VLOOKUP(G:G,list!B:F,5,FALSE) -> - | R31: =VLOOKUP(G:G,list!B:D,3,FALSE) -> N
B32: 27 | C32: =VLOOKUP(G:G,list!B:D,2,FALSE) -> 원작료 | D32: 국내 | E32: 독점 | F32: 카카오웹툰 | G32: 악녀인데 요리를 너무 잘해 | H32: 45236 | I32: 46082 | J32: 272795.7 | K32: 0.6 | L32: 163676 | M32: =VLOOKUP(G:G,list!B:E,4,FALSE) -> 0.1 | N32: =ROUND(IF(M32="-",0,L32*M32),0) -> 16368 | O32: =L32-N32 -> 147308 | Q32: =VLOOKUP(G:G,list!B:F,5,FALSE) -> - | R32: =VLOOKUP(G:G,list!B:D,3,FALSE) -> N
B33: 28 | C33: =VLOOKUP(G:G,list!B:D,2,FALSE) -> 원작료 | D33: 일본 | E33: 독점 | F33: 픽코마 | G33: 마족의 계약 | H33: 44359 | I33: 46054 | J33: 138812 | K33: 0.224 | L33: 27988 | M33: =VLOOKUP(G:G,list!B:E,4,FALSE) -> 0.1 | N33: =ROUND(IF(M33="-",0,L33*M33),0) -> 2799 | O33: =L33-N33 -> 25189 | Q33: =VLOOKUP(G:G,list!B:F,5,FALSE) -> 웹소설본부 | R33: =VLOOKUP(G:G,list!B:D,3,FALSE) -> Y
B34: 29 | C34: =VLOOKUP(G:G,list!B:D,2,FALSE) -> 원작료 | D34: 일본 | E34: 독점 | F34: 픽코마 | G34: 악역에게 청혼받았습니다 | H34: 44629 | I34: 46054 | J34: 584833 | K34: 0.224 | L34: 117908 | M34: =VLOOKUP(G:G,list!B:E,4,FALSE) -> 0.1 | N34: =ROUND(IF(M34="-",0,L34*M34),0) -> 11791 | O34: =L34-N34 -> 106117 | Q34: =VLOOKUP(G:G,list!B:F,5,FALSE) -> 웹소설본부 | R34: =VLOOKUP(G:G,list!B:D,3,FALSE) -> Y
B35: 30 | C35: =VLOOKUP(G:G,list!B:D,2,FALSE) -> 작가기획 | D35: 일본 | E35: 독점 | F35: 픽코마 | G35: 별이 빈 소원 | H35: 44773 | I35: 46054 | J35: 1706 | K35: 0.224 | L35: 354 | M35: =VLOOKUP(G:G,list!B:E,4,FALSE) -> - | N35: =ROUND(IF(M35="-",0,L35*M35),0) -> 0 | O35: =L35-N35 -> 354 | Q35: =VLOOKUP(G:G,list!B:F,5,FALSE) -> - | R35: =VLOOKUP(G:G,list!B:D,3,FALSE) -> Y
B36: 31 | C36: =VLOOKUP(G:G,list!B:D,2,FALSE) -> 원작료 | D36: 일본 | E36: 독점 | F36: 픽코마 | G36: 입술 좀 빌려주세요 | H36: 44784 | I36: 46054 | J36: 82491 | K36: 0.224 | L36: 16631 | M36: =VLOOKUP(G:G,list!B:E,4,FALSE) -> 0.1 | N36: =ROUND(IF(M36="-",0,L36*M36),0) -> 1663 | O36: =L36-N36 -> 14968 | Q36: =VLOOKUP(G:G,list!B:F,5,FALSE) -> 웹소설본부 | R36: =VLOOKUP(G:G,list!B:D,3,FALSE) -> Y
B37: 32 | C37: =VLOOKUP(G:G,list!B:D,2,FALSE) -> 원작료 | D37: 일본 | E37: 독점 | F37: 픽코마 | G37: 만렙으로 사는 법 | H37: 44808 | I37: 46054 | J37: 236095 | K37: 0.224 | L37: 47597 | M37: =VLOOKUP(G:G,list!B:E,4,FALSE) -> 0.11 | N37: =ROUND(IF(M37="-",0,L37*M37),0) -> 5236 | O37: =L37-N37 -> 42361 | Q37: =VLOOKUP(G:G,list!B:F,5,FALSE) -> - | R37: =VLOOKUP(G:G,list!B:D,3,FALSE) -> N
... B40: 35 | C40: =VLOOKUP(G:G,list!B:D,2,FALSE) -> 원작료 | D40: 일본 | E40: 독점 | F40: 픽코마 | G40: 책만 보고 탑배우! | H40: 45035 | I40: 46054 | J40: 1339200 | K40: 0.224 | L40: 269987 | M40: =VLOOKUP(G:G,list!B:E,4,FALSE) -> 0.1 | N40: =ROUND(IF(M40="-",0,L40*M40),0) -> 26999 | O40: =L40-N40 -> 242988 | Q40: =VLOOKUP(G:G,list!B:F,5,FALSE) -> - | R40: =VLOOKUP(G:G,list!B:D,3,FALSE) -> Y
B41: 36 | C41: =VLOOKUP(G:G,list!B:D,2,FALSE) -> 작가기획 | D41: 일본 | E41: 독점 | F41: 픽코마 | G41: 너를 만지면 | H41: 45116 | I41: 46054 | J41: 0 | K41: 0.224 | L41: 0 | M41: =VLOOKUP(G:G,list!B:E,4,FALSE) -> - | N41: =ROUND(IF(M41="-",0,L41*M41),0) -> 0 | O41: =L41-N41 -> 0 | P41: *매출없음 | Q41: =VLOOKUP(G:G,list!B:F,5,FALSE) -> - | R41: =VLOOKUP(G:G,list!B:D,3,FALSE) -> N
B42: 37 | C42: =VLOOKUP(G:G,list!B:D,2,FALSE) -> 원작료 | D42: 일본 | E42: 독점 | F42: 픽코마 | G42: 그 남자, 처음, 로맨틱 | H42: 45237 | I42: 46054 | J42: 42667 | K42: 0.224 | L42: 8606 | M42: =VLOOKUP(G:G,list!B:E,4,FALSE) -> 0.1 | N42: =ROUND(IF(M42="-",0,L42*M42),0) -> 861 | O42: =L42-N42 -> 7745 | Q42: =VLOOKUP(G:G,list!B:F,5,FALSE) -> 웹소설본부 | R42: =VLOOKUP(G:G,list!B:D,3,FALSE) -> Y
B43: 38 | C43: =VLOOKUP(G:G,list!B:D,2,FALSE) -> 원작료 | D43: 일본 | E43: 독점 | F43: 픽코마 | G43: 악녀인데 요리를 너무 잘해 | H43: 45364 | I43: 46054 | J43: 1217455 | K43: 0.224 | L43: 245439 | M43: =VLOOKUP(G:G,list!B:E,4,FALSE) -> 0.1 | N43: =ROUND(IF(M43="-",0,L43*M43),0) -> 24544 | O43: =L43-N43 -> 220895 | Q43: =VLOOKUP(G:G,list!B:F,5,FALSE) -> - | R43: =VLOOKUP(G:G,list!B:D,3,FALSE) -> N
B44: 39 | C44: =VLOOKUP(G:G,list!B:D,2,FALSE) -> 외부제작 | D44: 일본 | E44: 독점 | F44: 픽코마 | G44: 강호, 미치다! | H44: 45412 | I44: 46054 | J44: 271367 | K44: 0.224 | L44: 54714 | M44: =VLOOKUP(G:G,list!B:E,4,FALSE) -> - | N44: =ROUND(IF(M44="-",0,L44*M44),0) -> 0 | O44: =L44-N44 -> 54714 | Q44: =VLOOKUP(G:G,list!B:F,5,FALSE) -> - | R44: =VLOOKUP(G:G,list!B:D,3,FALSE) -> N
B45: 40 | C45: =VLOOKUP(G:G,list!B:D,2,FALSE) -> 원작료 | D45: 태국 | E45: 독점 | F45: 카카오페이지 | G45: 악녀인데 남주를 주워버렸다 | H45: 45901 | I45: 46082 | J45: 364 | K45: 0.35 | L45: 127 | M45: =VLOOKUP(G:G,list!B:E,4,FALSE) -> 0.1 | N45: =ROUND(IF(M45="-",0,L45*M45),0) -> 13 | O45: =L45-N45 -> 114 | Q45: =VLOOKUP(G:G,list!B:F,5,FALSE) -> 웹소설본부 | R45: =VLOOKUP(G:G,list!B:D,3,FALSE) -> Y
B46: 41 | C46: =VLOOKUP(G:G,list!B:D,2,FALSE) -> 작가기획 | D46: 국내 | E46: 독점 | F46: 봄툰 | G46: 달빛 하울링 | H46: 43810 | I46: 46082 | J46: 21240 | K46: 웹(45%)/앱(35%) | L46: 7884 | M46: =VLOOKUP(G:G,list!B:E,4,FALSE) -> - | N46: =ROUND(IF(M46="-",0,L46*M46),0) -> 0 | O46: =L46-N46 -> 7884 | Q46: =VLOOKUP(G:G,list!B:F,5,FALSE) -> - | R46: =VLOOKUP(G:G,list!B:D,3,FALSE) -> Y
B47: 42 | C47: =VLOOKUP(G:G,list!B:D,2,FALSE) -> 작가기획 | D47: 국내 | E47: 독점 | F47: 봄툰 | G47: 두 개의 순간 | H47: 43852 | I47: 46082 | J47: 7560 | K47: 웹(45%)/앱(35%) | L47: 2646 | M47: =VLOOKUP(G:G,list!B:E,4,FALSE) -> - | N47: =ROUND(IF(M47="-",0,L47*M47),0) -> 0 | O47: =L47-N47 -> 2646 | Q47: =VLOOKUP(G:G,list!B:F,5,FALSE) -> - | R47: =VLOOKUP(G:G,list!B:D,3,FALSE) -> Y
...

Sheet 26.04
B2: 2026.04월 (매입) 지급 대상 유통 정산 금액 & 정산 순매출
B3: - 수성 입금 기간 : 2026.03.01~2026.03.31
I4: 합계 | J4: =SUBTOTAL(109,J6:J1048576) -> 22389483 | L4: =SUBTOTAL(109,L6:L1048576) -> 9092749 | N4: =SUBTOTAL(109,N6:N1048576) -> 834437 | O4: =SUBTOTAL(109,O6:O1048576) -> 8258312
B5: NO | C5: 항목 | D5: 판매 국가 | E5: 구분 (독/비독) | F5: 플랫폼명 | G5: 작품명 | H5: 런칭일 | I5: 서비스월 (=판매월) | J5: 총매출(A) (요약본 정산기준매출) | K5: RS율 (테라핀) | L5: 정산기준매출(B) (테라핀) | M5: RS율 (원작사) | N5: 원작료(C) (B×원작사 RS율) | O5: 정산순매출 (B－C) | P5: 비고1 | Q5: 웹소설본부 원작여부 | R5: RS 대상여부 (외주작가)
B6: 1 | C6: =VLOOKUP(G:G,list!B:D,2,FALSE) -> 외부제작 | D6: 국내 | E6: 독점 | F6: 카카오페이지_앙상블 | G6: 블러디 체어 | H6: 44629 | I6: 46054 | J6: 279106 | K6: 0.6 | L6: 167463 | M6: =VLOOKUP(G:G,list!B:E,4,FALSE) -> - | N6: =ROUND(IF(M6="-",0,L6*M6),0) -> 0 | O6: =L6-N6 -> 167463 | Q6: =VLOOKUP(G:G,list!B:F,5,FALSE) -> - | R6: =VLOOKUP(G:G,list!B:D,3,FALSE) -> N
B7: 2 | C7: =VLOOKUP(G:G,list!B:D,2,FALSE) -> 외부제작 | D7: 국내 | E7: 독점 | F7: 카카오페이지_앙상블 | G7: 검신 | H7: 45057 | I7: 46054 | J7: 101649.6 | K7: 0.6 | L7: 60989 | M7: =VLOOKUP(G:G,list!B:E,4,FALSE) -> - | N7: =ROUND(IF(M7="-",0,L7*M7),0) -> 0 | O7: =L7-N7 -> 60989 | Q7: =VLOOKUP(G:G,list!B:F,5,FALSE) -> - | R7: =VLOOKUP(G:G,list!B:D,3,FALSE) -> N
B8: 3 | C8: =VLOOKUP(G:G,list!B:D,2,FALSE) -> 외부제작 | D8: 국내 | E8: 독점 | F8: 카카오페이지_앙상블 | G8: 강호, 미치다! | H8: 45204 | I8: 46054 | J8: 217351 | K8: 0.6 | L8: 130411 | M8: =VLOOKUP(G:G,list!B:E,4,FALSE) -> - | N8: =ROUND(IF(M8="-",0,L8*M8),0) -> 0 | O8: =L8-N8 -> 130411 | Q8: =VLOOKUP(G:G,list!B:F,5,FALSE) -> - | R8: =VLOOKUP(G:G,list!B:D,3,FALSE) -> N
B9: 4 | C9: =VLOOKUP(G:G,list!B:D,2,FALSE) -> 원작료 | D9: 국내 | E9: 독점 | F9: 카카오페이지 | G9: 마족의 계약 | H9: 44199 | I9: 46054 | J9: 38802 | K9: 0.6 | L9: 23282 | M9: =VLOOKUP(G:G,list!B:E,4,FALSE) -> 0.1 | N9: =ROUND(IF(M9="-",0,L9*M9),0) -> 2328 | O9: =L9-N9 -> 20954 | Q9: =VLOOKUP(G:G,list!B:F,5,FALSE) -> 웹소설본부 | R9: =VLOOKUP(G:G,list!B:D,3,FALSE) -> Y
B10: 5 | C10: =VLOOKUP(G:G,list!B:D,2,FALSE) -> 원작료 | D10: 국내 | E10: 독점 | F10: 카카오페이지 | G10: 악역에게 청혼받았습니다 | H10: 44372 | I10: 46054 | J10: 156339 | K10: 0.6 | L10: 93801 | M10: =VLOOKUP(G:G,list!B:E,4,FALSE) -> 0.1 | N10: =ROUND(IF(M10="-",0,L10*M10),0) -> 9380 | O10: =L10-N10 -> 84421 | Q10: =VLOOKUP(G:G,list!B:F,5,FALSE) -> 웹소설본부 | R10: =VLOOKUP(G:G,list!B:D,3,FALSE) -> Y
B11: 6 | C11: =VLOOKUP(G:G,list!B:D,2,FALSE) -> 작가기획 | D11: 국내 | E11: 독점 | F11: 카카오페이지 | G11: 별이 빈 소원 | H11: 44608 | I11: 46054 | J11: -14 | K11: 0.6 | L11: -8 | M11: =VLOOKUP(G:G,list!B:E,4,FALSE) -> - | N11: =ROUND(IF(M11="-",0,L11*M11),0) -> 0 | O11: =L11-N11 -> -8 | Q11: =VLOOKUP(G:G,list!B:F,5,FALSE) -> - | R11: =VLOOKUP(G:G,list!B:D,3,FALSE) -> Y
B12: 7 | C12: =VLOOKUP(G:G,list!B:D,2,FALSE) -> 원작료 | D12: 국내 | E12: 독점 | F12: 카카오페이지 | G12: 입술 좀 빌려주세요 | H12: 44639 | I12: 46054 | J12: 232496 | K12: 0.6 | L12: 139497 | M12: =VLOOKUP(G:G,list!B:E,4,FALSE) -> 0.1 | N12: =ROUND(IF(M12="-",0,L12*M12),0) -> 13950 | O12: =L12-N12 -> 125547 | Q12: =VLOOKUP(G:G,list!B:F,5,FALSE) -> 웹소설본부 | R12: =VLOOKUP(G:G,list!B:D,3,FALSE) -> Y
B13: 8 | C13: =VLOOKUP(G:G,list!B:D,2,FALSE) -> 원작료 | D13: 국내 | E13: 독점 | F13: 카카오페이지 | G13: 악녀인데 남주를 주워버렸다 | H13: 44691 | I13: 46054 | J13: 27456.6 | K13: 0.6 | L13: 16474 | M13: =VLOOKUP(G:G,list!B:E,4,FALSE) -> 0.1 | N13: =ROUND(IF(M13="-",0,L13*M13),0) -> 1647 | O13: =L13-N13 -> 14827 | Q13: =VLOOKUP(G:G,list!B:F,5,FALSE) -> 웹소설본부 | R13: =VLOOKUP(G:G,list!B:D,3,FALSE) -> Y
B14: 9 | C14: =VLOOKUP(G:G,list!B:D,2,FALSE) -> 원작료 | D14: 국내 | E14: 독점 | F14: 카카오페이지 | G14: 만렙으로 사는 법 | H14: 44709 | I14: 46054 | J14: 79102.5 | K14: 0.6 | L14: 47461 | M14: =VLOOKUP(G:G,list!B:E,4,FALSE) -> 0.11 | N14: =ROUND(IF(M14="-",0,L14*M14),0) -> 5221 | O14: =L14-N14 -> 42240 | Q14: =VLOOKUP(G:G,list!B:F,5,FALSE) -> - | R14: =VLOOKUP(G:G,list!B:D,3,FALSE) -> N
B15: 10 | C15: =VLOOKUP(G:G,list!B:D,2,FALSE) -> 원작료 | D15: 국내 | E15: 독점 | F15: 카카오페이지 | G15: 책만 보고 탑배우! | H15: 44801 | I15: 46054 | J15: 364877.2 | K15: 0.6 | L15: 218926 | M15: =VLOOKUP(G:G,list!B:E,4,FALSE) -> 0.1 | N15: =ROUND(IF(M15="-",0,L15*M15),0) -> 21893 | O15: =L15-N15 -> 197033 | Q15: =VLOOKUP(G:G,list!B:F,5,FALSE) -> - | R15: =VLOOKUP(G:G,list!B:D,3,FALSE) -> Y
B16: 11 | C16: =VLOOKUP(G:G,list!B:D,2,FALSE) -> 원작료 | D16: 국내 | E16: 독점 | F16: 카카오페이지 | G16: 그 남자, 처음, 로맨틱 | H16: 44831 | I16: 46054 | J16: 53065 | K16: 0.6 | L16: 31839 | M16: =VLOOKUP(G:G,list!B:E,4,FALSE) -> 0.1 | N16: =ROUND(IF(M16="-",0,L16*M16),0) -> 3184 | O16: =L16-N16 -> 28655 | Q16: =VLOOKUP(G:G,list!B:F,5,FALSE) -> 웹소설본부 | R16: =VLOOKUP(G:G,list!B:D,3,FALSE) -> Y
B17: 12 | C17: =VLOOKUP(G:G,list!B:D,2,FALSE) -> 작가기획 | D17: 국내 | E17: 독점 | F17: 카카오페이지 | G17: 너를 만지면 | H17: 44851 | I17: 46054 | J17: 12432 | K17: 0.7 | L17: 8702 | M17: =VLOOKUP(G:G,list!B:E,4,FALSE) -> - | N17: =ROUND(IF(M17="-",0,L17*M17),0) -> 0 | O17: =L17-N17 -> 8702 | Q17: =VLOOKUP(G:G,list!B:F,5,FALSE) -> - | R17: =VLOOKUP(G:G,list!B:D,3,FALSE) -> N
... B34: 29 | C34: =VLOOKUP(G:G,list!B:D,2,FALSE) -> 원작료 | D34: 일본 | E34: 독점 | F34: 픽코마 | G34: 악역에게 청혼받았습니다 | H34: 44629 | I34: 46023 | J34: 730297 | K34: 0.224 | L34: 147236 | M34: =VLOOKUP(G:G,list!B:E,4,FALSE) -> 0.1 | N34: =ROUND(IF(M34="-",0,L34*M34),0) -> 14724 | O34: =L34-N34 -> 132512 | Q34: =VLOOKUP(G:G,list!B:F,5,FALSE) -> 웹소설본부 | R34: =VLOOKUP(G:G,list!B:D,3,FALSE) -> Y
B35: 30 | C35: =VLOOKUP(G:G,list!B:D,2,FALSE) -> 작가기획 | D35: 일본 | E35: 독점 | F35: 픽코마 | G35: 별이 빈 소원 | H35: 44773 | I35: 46023 | J35: 0 | K35: 0.224 | L35: 0 | M35: =VLOOKUP(G:G,list!B:E,4,FALSE) -> - | N35: =ROUND(IF(M35="-",0,L35*M35),0) -> 0 | O35: =L35-N35 -> 0 | P35: *매출없음 | Q35: =VLOOKUP(G:G,list!B:F,5,FALSE) -> - | R35: =VLOOKUP(G:G,list!B:D,3,FALSE) -> Y
B36: 31 | C36: =VLOOKUP(G:G,list!B:D,2,FALSE) -> 원작료 | D36: 일본 | E36: 독점 | F36: 픽코마 | G36: 입술 좀 빌려주세요 | H36: 44784 | I36: 46023 | J36: 237006 | K36: 0.224 | L36: 47781 | M36: =VLOOKUP(G:G,list!B:E,4,FALSE) -> 0.1 | N36: =ROUND(IF(M36="-",0,L36*M36),0) -> 4778 | O36: =L36-N36 -> 43003 | Q36: =VLOOKUP(G:G,list!B:F,5,FALSE) -> 웹소설본부 | R36: =VLOOKUP(G:G,list!B:D,3,FALSE) -> Y
B37: 32 | C37: =VLOOKUP(G:G,list!B:D,2,FALSE) -> 원작료 | D37: 일본 | E37: 독점 | F37: 픽코마 | G37: 만렙으로 사는 법 | H37: 44808 | I37: 46023 | J37: 270459 | K37: 0.224 | L37: 54531 | M37: =VLOOKUP(G:G,list!B:E,4,FALSE) -> 0.11 | N37: =ROUND(IF(M37="-",0,L37*M37),0) -> 5998 | O37: =L37-N37 -> 48533 | Q37: =VLOOKUP(G:G,list!B:F,5,FALSE) -> - | R37: =VLOOKUP(G:G,list!B:D,3,FALSE) -> N
B38: 33 | C38: =VLOOKUP(G:G,list!B:D,2,FALSE) -> 원작료 | D38: 일본 | E38: 독점 | F38: 픽코마 | G38: 악녀인데 남주를 주워버렸다 | H38: 44813 | I38: 46023 | J38: 243810 | K38: 0.224 | L38: 49157 | M38: =VLOOKUP(G:G,list!B:E,4,FALSE) -> 0.1 | N38: =ROUND(IF(M38="-",0,L38*M38),0) -> 4916 | O38: =L38-N38 -> 44241 | Q38: =VLOOKUP(G:G,list!B:F,5,FALSE) -> 웹소설본부 | R38: =VLOOKUP(G:G,list!B:D,3,FALSE) -> Y
B39: 34 | C39: =VLOOKUP(G:G,list!B:D,2,FALSE) -> 외부제작 | D39: 일본 | E39: 독점 | F39: 픽코마 | G39: 블러디 체어 | H39: 44825 | I39: 46023 | J39: 229635 | K39: 0.224 | L39: 46298 | M39: =VLOOKUP(G:G,list!B:E,4,FALSE) -> - | N39: =ROUND(IF(M39="-",0,L39*M39),0) -> 0 | O39: =L39-N39 -> 46298 | Q39: =VLOOKUP(G:G,list!B:F,5,FALSE) -> - | R39: =VLOOKUP(G:G,list!B:D,3,FALSE) -> N
B40: 35 | C40: =VLOOKUP(G:G,list!B:D,2,FALSE) -> 원작료 | D40: 일본 | E40: 독점 | F40: 픽코마 | G40: 책만 보고 탑배우! | H40: 45035 | I40: 46023 | J40: 2963714 | K40: 0.224 | L40: 597486 | M40: =VLOOKUP(G:G,list!B:E,4,FALSE) -> 0.1 | N40: =ROUND(IF(M40="-",0,L40*M40),0) -> 59749 | O40: =L40-N40 -> 537737 | Q40: =VLOOKUP(G:G,list!B:F,5,FALSE) -> - | R40: =VLOOKUP(G:G,list!B:D,3,FALSE) -> Y
B41: 36 | C41: =VLOOKUP(G:G,list!B:D,2,FALSE) -> 작가기획 | D41: 일본 | E41: 독점 | F41: 픽코마 | G41: 너를 만지면 | H41: 45116 | I41: 46023 | J41: 0 | K41: 0.224 | L41: 0 | M41: =VLOOKUP(G:G,list!B:E,4,FALSE) -> - | N41: =ROUND(IF(M41="-",0,L41*M41),0) -> 0 | O41: =L41-N41 -> 0 | P41: *매출없음 | Q41: =VLOOKUP(G:G,list!B:F,5,FALSE) -> - | R41: =VLOOKUP(G:G,list!B:D,3,FALSE) -> N
B42: 37 | C42: =VLOOKUP(G:G,list!B:D,2,FALSE) -> 원작료 | D42: 일본 | E42: 독점 | F42: 픽코마 | G42: 그 남자, 처음, 로맨틱 | H42: 45237 | I42: 46023 | J42: 79380 | K42: 0.224 | L42: 16005 | M42: =VLOOKUP(G:G,list!B:E,4,FALSE) -> 0.1 | N42: =ROUND(IF(M42="-",0,L42*M42),0) -> 1601 | O42: =L42-N42 -> 14404 | Q42: =VLOOKUP(G:G,list!B:F,5,FALSE) -> 웹소설본부 | R42: =VLOOKUP(G:G,list!B:D,3,FALSE) -> Y
B43: 38 | C43: =VLOOKUP(G:G,list!B:D,2,FALSE) -> 원작료 | D43: 일본 | E43: 독점 | F43: 픽코마 | G43: 악녀인데 요리를 너무 잘해 | H43: 45364 | I43: 46023 | J43: 1488944 | K43: 0.224 | L43: 300172 | M43: =VLOOKUP(G:G,list!B:E,4,FALSE) -> 0.1 | N43: =ROUND(IF(M43="-",0,L43*M43),0) -> 30017 | O43: =L43-N43 -> 270155 | Q43: =VLOOKUP(G:G,list!B:F,5,FALSE) -> - | R43: =VLOOKUP(G:G,list!B:D,3,FALSE) -> N
B44: 39 | C44: =VLOOKUP(G:G,list!B:D,2,FALSE) -> 외부제작 | D44: 일본 | E44: 독점 | F44: 픽코마 | G44: 강호, 미치다! | H44: 45412 | I44: 46023 | J44: 395766 | K44: 0.224 | L44: 79793 | M44: =VLOOKUP(G:G,list!B:E,4,FALSE) -> - | N44: =ROUND(IF(M44="-",0,L44*M44),0) -> 0 | O44: =L44-N44 -> 79793 | Q44: =VLOOKUP(G:G,list!B:F,5,FALSE) -> - | R44: =VLOOKUP(G:G,list!B:D,3,FALSE) -> N
B45: 40 | C45: =VLOOKUP(G:G,list!B:D,2,FALSE) -> 원작료 | D45: 태국 | E45: 독점 | F45: 카카오페이지 | G45: 악녀인데 남주를 주워버렸다 | H45: 45901 | I45: 46054 | J45: 0 | K45: 0.35 | L45: 0 | M45: =VLOOKUP(G:G,list!B:E,4,FALSE) -> 0.1 | N45: =ROUND(IF(M45="-",0,L45*M45),0) -> 0 | O45: =L45-N45 -> 0 | P45: *매출없음 | Q45: =VLOOKUP(G:G,list!B:F,5,FALSE) -> 웹소설본부 | R45: =VLOOKUP(G:G,list!B:D,3,FALSE) -> Y
B46: 41 | C46: =VLOOKUP(G:G,list!B:D,2,FALSE) -> 작가기획 | D46: 국내 | E46: 독점 | F46: 봄툰 | G46: 달빛 하울링 | H46: 43810 | I46: 46054 | J46: 50940 | K46: 웹(45%)/앱(35%) | L46: 18207 | M46: =VLOOKUP(G:G,list!B:E,4,FALSE) -> - | N46: =ROUND(IF(M46="-",0,L46*M46),0) -> 0 | O46: =L46-N46 -> 18207 | Q46: =VLOOKUP(G:G,list!B:F,5,FALSE) -> - | R46: =VLOOKUP(G:G,list!B:D,3,FALSE) -> Y
B47: 42 | C47: =VLOOKUP(G:G,list!B:D,2,FALSE) -> 작가기획 | D47: 국내 | E47: 독점 | F47: 봄툰 | G47: 두 개의 순간 | H47: 43852 | I47: 46054 | J47: 1620 | K47: 웹(45%)/앱(35%) | L47: 567 | M47: =VLOOKUP(G:G,list!B:E,4,FALSE) -> - | N47: =ROUND(IF(M47="-",0,L47*M47),0) -> 0 | O47: =L47-N47 -> 567 | Q47: =VLOOKUP(G:G,list!B:F,5,FALSE) -> - | R47: =VLOOKUP(G:G,list!B:D,3,FALSE) -> Y
B48: 43 | C48: =VLOOKUP(G:G,list!B:D,2,FALSE) -> 작가기획 | D48: 국내 | E48: 독점 | F48: 레진코믹스(=봄툰B2BC) | G48: 달빛 하울링 | H48: 45124 | I48: 46023 | J48: 119514 | K48: 0.5 | L48: 59757 | M48: =VLOOKUP(G:G,list!B:E,4,FALSE) -> - | N48: =ROUND(IF(M48="-",0,L48*M48),0) -> 0 | O48: =L48-N48 -> 59757 | Q48: =VLOOKUP(G:G,list!B:F,5,FALSE) -> - | R48: =VLOOKUP(G:G,list!B:D,3,FALSE) -> Y
B49: 44 | C49: =VLOOKUP(G:G,list!B:D,2,FALSE) -> 작가기획 | D49: 국내 | E49: 독점 | F49: 레진코믹스(=봄툰B2BC) | G49: 두 개의 순간 | H49: 44513 | I49: 46023 | J49: 18453 | K49: 0.5 | L49: 9227 | M49: =VLOOKUP(G:G,list!B:E,4,FALSE) -> - | N49: =ROUND(IF(M49="-",0,L49*M49),0) -> 0 | O49: =L49-N49 -> 9227 | Q49: =VLOOKUP(G:G,list!B:F,5,FALSE) -> - | R49: =VLOOKUP(G:G,list!B:D,3,FALSE) -> Y
B50: 45 | C50: =VLOOKUP(G:G,list!B:D,2,FALSE) -> 원작료 | D50: 독일 | E50: 독점(12개월) | F50: 레진 | G50: 마족의 계약 | H50: 44586 | I50: 46054 | J50: 80975 | K50: 0.4 | L50: 32390 | M50: =VLOOKUP(G:G,list!B:E,4,FALSE) -> 0.1 | N50: =ROUND(IF(M50="-",0,L50*M50),0) -> 3239 | O50: =L50-N50 -> 29151 | Q50: =VLOOKUP(G:G,list!B:F,5,FALSE) -> 웹소설본부 | R50: =VLOOKUP(G:G,list!B:D,3,FALSE) -> Y
B51: 46 | C51: =VLOOKUP(G:G,list!B:D,2,FALSE) -> 작가기획 | D51: 독일 | E51: 독점 | F51: 레진 | G51: 달빛 하울링 | H51: 44992 | I51: 46054 | J51: 120140 | K51: 0.4 | L51: 48056 | M51: =VLOOKUP(G:G,list!B:E,4,FALSE) -> - | N51: =ROUND(IF(M51="-",0,L51*M51),0) -> 0 | O51: =L51-N51 -> 48056 | Q51: =VLOOKUP(G:G,list!B:F,5,FALSE) -> - | R51: =VLOOKUP(G:G,list!B:D,3,FALSE) -> Y
B52: 47 | C52: =VLOOKUP(G:G,list!B:D,2,FALSE) -> 작가기획 | D52: 독일 | E52: 독점 | F52: 레진 | G52: 두 개의 순간 | H52: 45169 | I52: 46054 | J52: 0 | K52: 0.4 | L52: 0 | M52: =VLOOKUP(G:G,list!B:E,4,FALSE) -> - | N52: =ROUND(IF(M52="-",0,L52*M52),0) -> 0 | O52: =L52-N52 -> 0 | P52: *매출없음 | Q52: =VLOOKUP(G:G,list!B:F,5,FALSE) -> - | R52: =VLOOKUP(G:G,list!B:D,3,FALSE) -> Y
B53: 48 | C53: =VLOOKUP(G:G,list!B:D,2,FALSE) -> 작가기획 | D53: 프랑스 | E53: 독점 | F53: 레진 | G53: 두 개의 순간 | H53: 43921 | I53: 46054 | J53: 38358 | K53: 0.4 | L53: 15343 | M53: =VLOOKUP(G:G,list!B:E,4,FALSE) -> - | N53: =ROUND(IF(M53="-",0,L53*M53),0) -> 0 | O53: =L53-N53 -> 15343 | Q53: =VLOOKUP(G:G,list!B:F,5,FALSE) -> - | R53: =VLOOKUP(G:G,list!B:D,3,FALSE) -> Y
B54: 49 | C54: =VLOOKUP(G:G,list!B:D,2,FALSE) -> 작가기획 | D54: 프랑스 | E54: 독점 | F54: 레진 | G54: 달빛 하울링 | H54: 43941 | I54: 46054 | J54: 40275 | K54: 0.4 | L54: 16110 | M54: =VLOOKUP(G:G,list!B:E,4,FALSE) -> - | N54: =ROUND(IF(M54="-",0,L54*M54),0) -> 0 | O54: =L54-N54 -> 16110 | Q54: =VLOOKUP(G:G,list!B:F,5,FALSE) -> - | R54: =VLOOKUP(G:G,list!B:D,3,FALSE) -> Y
B55: 50 | C55: =VLOOKUP(G:G,list!B:D,2,FALSE) -> 원작료 | D55: 프랑스 | E55: 독점(12개월) | F55: 레진 | G55: 마족의 계약 | H55: 44258 | I55: 46054 | J55: 1150 | K55: 0.4 | L55: 460 | M55: =VLOOKUP(G:G,list!B:E,4,FALSE) -> 0.1 | N55: =ROUND(IF(M55="-",0,L55*M55),0) -> 46 | O55: =L55-N55 -> 414 | Q55: =VLOOKUP(G:G,list!B:F,5,FALSE) -> 웹소설본부 | R55: =VLOOKUP(G:G,list!B:D,3,FALSE) -> Y
B56: 51 | C56: =VLOOKUP(G:G,list!B:D,2,FALSE) -> 작가기획 | D56: 국내 | E56: 독점 | F56: 투믹스 | G56: 그놈 목소리 | H56: 44333 | I56: 46054 | J56: 0 | K56: 0.5 | L56: 0 | M56: =VLOOKUP(G:G,list!B:E,4,FALSE) -> - | N56: =ROUND(IF(M56="-",0,L56*M56),0) -> 0 | O56: =L56-N56 -> 0 | P56: *매출없음 | Q56: =VLOOKUP(G:G,list!B:F,5,FALSE) -> - | R56: =VLOOKUP(G:G,list!B:D,3,FALSE) -> N
B57: 52 | C57: =VLOOKUP(G:G,list!B:D,2,FALSE) -> 작가기획 | D57: 국내 | E57: 비독점 | F57: 투믹스 | G57: 아내바보 | H57: 44897 | I57: 46054 | J57: 50274 | K57: 0.5 | L57: 25137 | M57: =VLOOKUP(G:G,list!B:E,4,FALSE) -> - | N57: =ROUND(IF(M57="-",0,L57*M57),0) -> 0 | O57: =L57-N57 -> 25137 | Q57: =VLOOKUP(G:G,list!B:F,5,FALSE) -> - | R57: =VLOOKUP(G:G,list!B:D,3,FALSE) -> N
...

Sheet 26.03
B2: 2026.03월 (매입) 지급 대상 유통 정산 금액 & 정산 순매출 | H2: 만타 정액제 재계약 MG 정산 필요(이미 다 오픈한 거 계약 연장) / 1차 완료, 2차 완료
B3: - 수성 입금 기간 : 2026.02.01~2026.02.28
I4: 합계 | J4: =SUBTOTAL(109,J6:J1048576) -> 27046455 | L4: =SUBTOTAL(109,L6:L1048576) -> 13953195 | N4: =SUBTOTAL(109,N6:N1048576) -> 1318090 | O4: =SUBTOTAL(109,O6:O1048576) -> 12635105
B5: NO | C5: 항목 | D5: 판매 국가 | E5: 구분 (독/비독) | F5: 플랫폼명 | G5: 작품명 | H5: 런칭일 | I5: 서비스월 (=판매월) | J5: 총매출(A) (요약본 정산기준매출) | K5: RS율 (테라핀) | L5: 정산기준매출(B) (테라핀) | M5: RS율 (원작사) | N5: 원작료(C) (B×원작사 RS율) | O5: 정산순매출 (B－C) | P5: 비고1 | Q5: 웹소설본부 원작여부 | R5: RS 대상여부 (외주작가)
B6: 1 | C6: =VLOOKUP(G:G,list!B:D,2,FALSE) -> 외부제작 | D6: 국내 | E6: 독점 | F6: 카카오페이지_앙상블 | G6: 블러디 체어 | H6: 44629 | I6: 46023 | J6: 377984.8 | K6: 0.6 | L6: 226791 | M6: =VLOOKUP(G:G,list!B:E,4,FALSE) -> - | N6: =ROUND(IF(M6="-",0,L6*M6),0) -> 0 | O6: =L6-N6 -> 226791 | Q6: =VLOOKUP(G:G,list!B:F,5,FALSE) -> - | R6: =VLOOKUP(G:G,list!B:D,3,FALSE) -> N
B7: 2 | C7: =VLOOKUP(G:G,list!B:D,2,FALSE) -> 외부제작 | D7: 국내 | E7: 독점 | F7: 카카오페이지_앙상블 | G7: 검신 | H7: 45057 | I7: 46023 | J7: 72947 | K7: 0.6 | L7: 43769 | M7: =VLOOKUP(G:G,list!B:E,4,FALSE) -> - | N7: =ROUND(IF(M7="-",0,L7*M7),0) -> 0 | O7: =L7-N7 -> 43769 | Q7: =VLOOKUP(G:G,list!B:F,5,FALSE) -> - | R7: =VLOOKUP(G:G,list!B:D,3,FALSE) -> N
B8: 3 | C8: =VLOOKUP(G:G,list!B:D,2,FALSE) -> 외부제작 | D8: 국내 | E8: 독점 | F8: 카카오페이지_앙상블 | G8: 강호, 미치다! | H8: 45204 | I8: 46023 | J8: 202970.2 | K8: 0.6 | L8: 121783 | M8: =VLOOKUP(G:G,list!B:E,4,FALSE) -> - | N8: =ROUND(IF(M8="-",0,L8*M8),0) -> 0 | O8: =L8-N8 -> 121783 | Q8: =VLOOKUP(G:G,list!B:F,5,FALSE) -> - | R8: =VLOOKUP(G:G,list!B:D,3,FALSE) -> N
B9: 4 | C9: =VLOOKUP(G:G,list!B:D,2,FALSE) -> 원작료 | D9: 국내 | E9: 독점 | F9: 카카오페이지 | G9: 마족의 계약 | H9: 44199 | I9: 46023 | J9: 28707 | K9: 0.6 | L9: 17224 | M9: =VLOOKUP(G:G,list!B:E,4,FALSE) -> 0.1 | N9: =ROUND(IF(M9="-",0,L9*M9),0) -> 1722 | O9: =L9-N9 -> 15502 | Q9: =VLOOKUP(G:G,list!B:F,5,FALSE) -> 웹소설본부 | R9: =VLOOKUP(G:G,list!B:D,3,FALSE) -> Y
B10: 5 | C10: =VLOOKUP(G:G,list!B:D,2,FALSE) -> 원작료 | D10: 국내 | E10: 독점 | F10: 카카오페이지 | G10: 악역에게 청혼받았습니다 | H10: 44372 | I10: 46023 | J10: 162066 | K10: 0.6 | L10: 97240 | M10: =VLOOKUP(G:G,list!B:E,4,FALSE) -> 0.1 | N10: =ROUND(IF(M10="-",0,L10*M10),0) -> 9724 | O10: =L10-N10 -> 87516 | Q10: =VLOOKUP(G:G,list!B:F,5,FALSE) -> 웹소설본부 | R10: =VLOOKUP(G:G,list!B:D,3,FALSE) -> Y
B11: 6 | C11: =VLOOKUP(G:G,list!B:D,2,FALSE) -> 작가기획 | D11: 국내 | E11: 독점 | F11: 카카오페이지 | G11: 별이 빈 소원 | H11: 44608 | I11: 46023 | J11: 782 | K11: 0.6 | L11: 470 | M11: =VLOOKUP(G:G,list!B:E,4,FALSE) -> - | N11: =ROUND(IF(M11="-",0,L11*M11),0) -> 0 | O11: =L11-N11 -> 470 | Q11: =VLOOKUP(G:G,list!B:F,5,FALSE) -> - | R11: =VLOOKUP(G:G,list!B:D,3,FALSE) -> Y
B12: 7 | C12: =VLOOKUP(G:G,list!B:D,2,FALSE) -> 원작료 | D12: 국내 | E12: 독점 | F12: 카카오페이지 | G12: 입술 좀 빌려주세요 | H12: 44639 | I12: 46023 | J12: 337281.9 | K12: 0.6 | L12: 202370 | M12: =VLOOKUP(G:G,list!B:E,4,FALSE) -> 0.1 | N12: =ROUND(IF(M12="-",0,L12*M12),0) -> 20237 | O12: =L12-N12 -> 182133 | Q12: =VLOOKUP(G:G,list!B:F,5,FALSE) -> 웹소설본부 | R12: =VLOOKUP(G:G,list!B:D,3,FALSE) -> Y
B13: 8 | C13: =VLOOKUP(G:G,list!B:D,2,FALSE) -> 원작료 | D13: 국내 | E13: 독점 | F13: 카카오페이지 | G13: 악녀인데 남주를 주워버렸다 | H13: 44691 | I13: 46023 | J13: 59843.6 | K13: 0.6 | L13: 35907 | M13: =VLOOKUP(G:G,list!B:E,4,FALSE) -> 0.1 | N13: =ROUND(IF(M13="-",0,L13*M13),0) -> 3591 | O13: =L13-N13 -> 32316 | Q13: =VLOOKUP(G:G,list!B:F,5,FALSE) -> 웹소설본부 | R13: =VLOOKUP(G:G,list!B:D,3,FALSE) -> Y
